Workbook

Sheet GAD DISPATCHER SCHEDULE
E1: NETWORK OPERATIONS CENTER GUARANTEED ASSIGNED DISPATCHER SCHEDULE
F4: HOLD | G4: =TEXT(G5,"dddd") -> Saturday | H4: =TEXT(H5,"dddd") -> Sunday | I4: =TEXT(I5,"dddd") -> Monday | J4: =TEXT(J5,"dddd") -> Tuesday | K4: =TEXT(K5,"dddd") -> Wednesday | L4: =TEXT(L5,"dddd") -> Thursday | M4: =TEXT(M5,"dddd") -> Friday
C5: NAME | E5: DIVISION | F5: DOWN | G5: =Sheet1!F1 -> 45969 | H5: =+G5+1 -> 45970 | I5: =+H5+1 -> 45971 | J5: =+I5+1 -> 45972 | K5: =+J5+1 -> 45973 | L5: =+K5+1 -> 45974 | M5: =+L5+1 -> 45975
C6: KEYSTONE
B7: MV, CT, HE, HT | C7: {=_xlfn._xlws.FILTER(Sheet1!$A$2:$C$333,Sheet1!$C$2:$C$333='GAD DISPATCHER SCHEDULE'!$U$13)} -> ALLEN, RYAN | D7: 1026388 | E7: KEYSTONE -GAD | F7: =_xlfn.IFNA(VLOOKUP($D7,Sheet1!$B$2:$E$333,4,FALSE),"") -> 0 | G7: =IFERROR(VLOOKUP($D7,Sheet1!$B$2:$S$333,6,FALSE),"") -> HE-3 | H7: =IFERROR(VLOOKUP($D7,Sheet1!$B$2:$S$333,8,FALSE),"") -> S-SD | I7: =IFERROR(VLOOKUP($D7,Sheet1!$B$2:$S$333,10,FALSE),"") -> HE-3 | J7: =IFERROR(VLOOKUP($D7,Sheet1!$B$2:$S$333,12,FALSE),"") -> V-SD | K7: =IFERROR(VLOOKUP($D7,Sheet1!$B$2:$S$333,14,FALSE),"") -> OFF | L7: =IFERROR(VLOOKUP($D7,Sheet1!$B$2:$S$333,16,FALSE),"") -> OFF | M7: =IFERROR(VLOOKUP($D7,Sheet1!$B$2:$S$333,18,FALSE),"") -> V-SD
B8: MV, PE, RL, (CT-LE) | C8: FLEITES, FRANK | D8: 1030369 | E8: KEYSTONE -GAD | F8: =_xlfn.IFNA(VLOOKUP($D8,Sheet1!$B$2:$E$333,4,FALSE),"") -> CE-R | G8: =IFERROR(VLOOKUP($D8,Sheet1!$B$2:$S$333,6,FALSE),"") -> CE-1 | H8: =IFERROR(VLOOKUP($D8,Sheet1!$B$2:$S$333,8,FALSE),"") -> CE-1 | I8: =IFERROR(VLOOKUP($D8,Sheet1!$B$2:$S$333,10,FALSE),"") -> CE-2 | J8: =IFERROR(VLOOKUP($D8,Sheet1!$B$2:$S$333,12,FALSE),"") -> CE-2 | K8: =IFERROR(VLOOKUP($D8,Sheet1!$B$2:$S$333,14,FALSE),"") -> CE-3 | L8: =IFERROR(VLOOKUP($D8,Sheet1!$B$2:$S$333,16,FALSE),"") -> OFF | M8: =IFERROR(VLOOKUP($D8,Sheet1!$B$2:$S$333,18,FALSE),"") -> OFF
B9: PE, MV, CT, CE | C9: GEE, ASHLEY | D9: 1029340 | E9: KEYSTONE -GAD | F9: =_xlfn.IFNA(VLOOKUP($D9,Sheet1!$B$2:$E$333,4,FALSE),"") -> 0 | G9: =IFERROR(VLOOKUP($D9,Sheet1!$B$2:$S$333,6,FALSE),"") -> OFF | H9: =IFERROR(VLOOKUP($D9,Sheet1!$B$2:$S$333,8,FALSE),"") -> OFF | I9: =IFERROR(VLOOKUP($D9,Sheet1!$B$2:$S$333,10,FALSE),"") -> CT-1-POST | J9: =IFERROR(VLOOKUP($D9,Sheet1!$B$2:$S$333,12,FALSE),"") -> CT-1-POST | K9: =IFERROR(VLOOKUP($D9,Sheet1!$B$2:$S$333,14,FALSE),"") -> CT-1-POST | L9: =IFERROR(VLOOKUP($D9,Sheet1!$B$2:$S$333,16,FALSE),"") -> CT-1-POST | M9: =IFERROR(VLOOKUP($D9,Sheet1!$B$2:$S$333,18,FALSE),"") -> CT-1-POST
B10: HE, DH, HT | C10: GRUBBS, TUJUANA | D10: 1028259 | E10: KEYSTONE -GAD | F10: =_xlfn.IFNA(VLOOKUP($D10,Sheet1!$B$2:$E$333,4,FALSE),"") -> 0 | G10: =IFERROR(VLOOKUP($D10,Sheet1!$B$2:$S$333,6,FALSE),"") -> DH-3 | H10: =IFERROR(VLOOKUP($D10,Sheet1!$B$2:$S$333,8,FALSE),"") -> DH-3 | I10: =IFERROR(VLOOKUP($D10,Sheet1!$B$2:$S$333,10,FALSE),"") -> DH-3 | J10: =IFERROR(VLOOKUP($D10,Sheet1!$B$2:$S$333,12,FALSE),"") -> DT-3 | K10: =IFERROR(VLOOKUP($D10,Sheet1!$B$2:$S$333,14,FALSE),"") -> OFF | L10: =IFERROR(VLOOKUP($D10,Sheet1!$B$2:$S$333,16,FALSE),"") -> OFF | M10: =IFERROR(VLOOKUP($D10,Sheet1!$B$2:$S$333,18,FALSE),"") -> DT-1
B11: MV, AL, HT (HG) | C11: REEVES, JULIAN | D11: 1030405 | E11: KEYSTONE -GAD | F11: =_xlfn.IFNA(VLOOKUP($D11,Sheet1!$B$2:$E$333,4,FALSE),"") -> 0 | G11: =IFERROR(VLOOKUP($D11,Sheet1!$B$2:$S$333,6,FALSE),"") -> OFF | H11: =IFERROR(VLOOKUP($D11,Sheet1!$B$2:$S$333,8,FALSE),"") -> OFF | I11: =IFERROR(VLOOKUP($D11,Sheet1!$B$2:$S$333,10,FALSE),"") -> AL-2 | J11: =IFERROR(VLOOKUP($D11,Sheet1!$B$2:$S$333,12,FALSE),"") -> DH-3 | K11: =IFERROR(VLOOKUP($D11,Sheet1!$B$2:$S$333,14,FALSE),"") -> S-SD | L11: =IFERROR(VLOOKUP($D11,Sheet1!$B$2:$S$333,16,FALSE),"") -> AVAILABLE | M11: =IFERROR(VLOOKUP($D11,Sheet1!$B$2:$S$333,18,FALSE),"") -> DH-3
B12: HG, DH, HE | C12: REYNOLDS, RO | D12: 1031687 | E12: KEYSTONE -GAD | F12: =_xlfn.IFNA(VLOOKUP($D12,Sheet1!$B$2:$E$333,4,FALSE),"") -> 0 | G12: =IFERROR(VLOOKUP($D12,Sheet1!$B$2:$S$333,6,FALSE),"") -> CT-1 | H12: =IFERROR(VLOOKUP($D12,Sheet1!$B$2:$S$333,8,FALSE),"") -> CT-1 | I12: =IFERROR(VLOOKUP($D12,Sheet1!$B$2:$S$333,10,FALSE),"") -> OFF | J12: =IFERROR(VLOOKUP($D12,Sheet1!$B$2:$S$333,12,FALSE),"") -> OFF | K12: =IFERROR(VLOOKUP($D12,Sheet1!$B$2:$S$333,14,FALSE),"") -> CT-3 | L12: =IFERROR(VLOOKUP($D12,Sheet1!$B$2:$S$333,16,FALSE),"") -> PE-3 | M12: =IFERROR(VLOOKUP($D12,Sheet1!$B$2:$S$333,18,FALSE),"") -> CE-3
C13: TEKLU, BETH | D13: 1031123 | E13: KEYSTONE -GAD | F13: =_xlfn.IFNA(VLOOKUP($D13,Sheet1!$B$2:$E$333,4,FALSE),"") -> 0 | G13: =IFERROR(VLOOKUP($D13,Sheet1!$B$2:$S$333,6,FALSE),"") -> PE-2 | H13: =IFERROR(VLOOKUP($D13,Sheet1!$B$2:$S$333,8,FALSE),"") -> PE-3 | I13: =IFERROR(VLOOKUP($D13,Sheet1!$B$2:$S$333,10,FALSE),"") -> PE-3 | J13: =IFERROR(VLOOKUP($D13,Sheet1!$B$2:$S$333,12,FALSE),"") -> AVAILABLE | K13: =IFERROR(VLOOKUP($D13,Sheet1!$B$2:$S$333,14,FALSE),"") -> OFF | L13: =IFERROR(VLOOKUP($D13,Sheet1!$B$2:$S$333,16,FALSE),"") -> OFF | M13: =IFERROR(VLOOKUP($D13,Sheet1!$B$2:$S$333,18,FALSE),"") -> AVAILABLE | U13: KEYSTONE -GAD
C14: TUCKER, JUSTIN | D14: 1000910 | E14: KEYSTONE -GAD | F14: =_xlfn.IFNA(VLOOKUP($D14,Sheet1!$B$2:$E$333,4,FALSE),"") -> 0 | G14: =IFERROR(VLOOKUP($D14,Sheet1!$B$2:$S$333,6,FALSE),"") -> RL-1-POST | H14: =IFERROR(VLOOKUP($D14,Sheet1!$B$2:$S$333,8,FALSE),"") -> HE-1 | I14: =IFERROR(VLOOKUP($D14,Sheet1!$B$2:$S$333,10,FALSE),"") -> OFF | J14: =IFERROR(VLOOKUP($D14,Sheet1!$B$2:$S$333,12,FALSE),"") -> OFF | K14: =IFERROR(VLOOKUP($D14,Sheet1!$B$2:$S$333,14,FALSE),"") -> AL-1 | L14: =IFERROR(VLOOKUP($D14,Sheet1!$B$2:$S$333,16,FALSE),"") -> AL-1 | M14: =IFERROR(VLOOKUP($D14,Sheet1!$B$2:$S$333,18,FALSE),"") -> RL-2-POST | U14: GREATLAKES - GAD
F15: =_xlfn.IFNA(VLOOKUP($D15,Sheet1!$B$2:$E$333,4,FALSE),"") | G15: =IFERROR(VLOOKUP($D15,Sheet1!$B$2:$S$333,6,FALSE),"") | H15: =IFERROR(VLOOKUP($D15,Sheet1!$B$2:$S$333,8,FALSE),"") | I15: =IFERROR(VLOOKUP($D15,Sheet1!$B$2:$S$333,10,FALSE),"") | J15: =IFERROR(VLOOKUP($D15,Sheet1!$B$2:$S$333,12,FALSE),"") | K15: =IFERROR(VLOOKUP($D15,Sheet1!$B$2:$S$333,14,FALSE),"") | L15: =IFERROR(VLOOKUP($D15,Sheet1!$B$2:$S$333,16,FALSE),"") | M15: =IFERROR(VLOOKUP($D15,Sheet1!$B$2:$S$333,18,FALSE),"") | U15: MIDWEST - GAD
F16: =_xlfn.IFNA(VLOOKUP($D16,Sheet1!$B$2:$E$333,4,FALSE),"") | G16: =IFERROR(VLOOKUP($D16,Sheet1!$B$2:$S$333,6,FALSE),"") | H16: =IFERROR(VLOOKUP($D16,Sheet1!$B$2:$S$333,8,FALSE),"") | I16: =IFERROR(VLOOKUP($D16,Sheet1!$B$2:$S$333,10,FALSE),"") | J16: =IFERROR(VLOOKUP($D16,Sheet1!$B$2:$S$333,12,FALSE),"") | K16: =IFERROR(VLOOKUP($D16,Sheet1!$B$2:$S$333,14,FALSE),"") | L16: =IFERROR(VLOOKUP($D16,Sheet1!$B$2:$S$333,16,FALSE),"") | M16: =IFERROR(VLOOKUP($D16,Sheet1!$B$2:$S$333,18,FALSE),"") | U16: GULF - GAD
F17: =_xlfn.IFNA(VLOOKUP($D17,Sheet1!$B$2:$E$333,4,FALSE),"") | G17: =IFERROR(VLOOKUP($D17,Sheet1!$B$2:$S$333,6,FALSE),"") | H17: =IFERROR(VLOOKUP($D17,Sheet1!$B$2:$S$333,8,FALSE),"") | I17: =IFERROR(VLOOKUP($D17,Sheet1!$B$2:$S$333,10,FALSE),"") | J17: =IFERROR(VLOOKUP($D17,Sheet1!$B$2:$S$333,12,FALSE),"") | K17: =IFERROR(VLOOKUP($D17,Sheet1!$B$2:$S$333,14,FALSE),"") | L17: =IFERROR(VLOOKUP($D17,Sheet1!$B$2:$S$333,16,FALSE),"") | M17: =IFERROR(VLOOKUP($D17,Sheet1!$B$2:$S$333,18,FALSE),"") | U17: BLUE RIDGE - GAD
F18: =_xlfn.IFNA(VLOOKUP($D18,Sheet1!$B$2:$E$333,4,FALSE),"") | G18: =IFERROR(VLOOKUP($D18,Sheet1!$B$2:$S$333,6,FALSE),"") | H18: =IFERROR(VLOOKUP($D18,Sheet1!$B$2:$S$333,8,FALSE),"") | I18: =IFERROR(VLOOKUP($D18,Sheet1!$B$2:$S$333,10,FALSE),"") | J18: =IFERROR(VLOOKUP($D18,Sheet1!$B$2:$S$333,12,FALSE),"") | K18: =IFERROR(VLOOKUP($D18,Sheet1!$B$2:$S$333,14,FALSE),"") | L18: =IFERROR(VLOOKUP($D18,Sheet1!$B$2:$S$333,16,FALSE),"") | M18: =IFERROR(VLOOKUP($D18,Sheet1!$B$2:$S$333,18,FALSE),"")
F19: =_xlfn.IFNA(VLOOKUP($D19,Sheet1!$B$2:$E$333,4,FALSE),"") | G19: =IFERROR(VLOOKUP($D19,Sheet1!$B$2:$S$333,6,FALSE),"") | H19: =IFERROR(VLOOKUP($D19,Sheet1!$B$2:$S$333,8,FALSE),"") | I19: =IFERROR(VLOOKUP($D19,Sheet1!$B$2:$S$333,10,FALSE),"") | J19: =IFERROR(VLOOKUP($D19,Sheet1!$B$2:$S$333,12,FALSE),"") | K19: =IFERROR(VLOOKUP($D19,Sheet1!$B$2:$S$333,14,FALSE),"") | L19: =IFERROR(VLOOKUP($D19,Sheet1!$B$2:$S$333,16,FALSE),"") | M19: =IFERROR(VLOOKUP($D19,Sheet1!$B$2:$S$333,18,FALSE),"")
F20: =_xlfn.IFNA(VLOOKUP($D20,Sheet1!$B$2:$E$333,4,FALSE),"") | G20: =IFERROR(VLOOKUP($D20,Sheet1!$B$2:$S$333,6,FALSE),"") | H20: =IFERROR(VLOOKUP($D20,Sheet1!$B$2:$S$333,8,FALSE),"") | I20: =IFERROR(VLOOKUP($D20,Sheet1!$B$2:$S$333,10,FALSE),"") | J20: =IFERROR(VLOOKUP($D20,Sheet1!$B$2:$S$333,12,FALSE),"") | K20: =IFERROR(VLOOKUP($D20,Sheet1!$B$2:$S$333,14,FALSE),"") | L20: =IFERROR(VLOOKUP($D20,Sheet1!$B$2:$S$333,16,FALSE),"") | M20: =IFERROR(VLOOKUP($D20,Sheet1!$B$2:$S$333,18,FALSE),"")
F21: =_xlfn.IFNA(VLOOKUP($D21,Sheet1!$B$2:$E$333,4,FALSE),"") | G21: =IFERROR(VLOOKUP($D21,Sheet1!$B$2:$S$333,6,FALSE),"") | H21: =IFERROR(VLOOKUP($D21,Sheet1!$B$2:$S$333,8,FALSE),"") | I21: =IFERROR(VLOOKUP($D21,Sheet1!$B$2:$S$333,10,FALSE),"") | J21: =IFERROR(VLOOKUP($D21,Sheet1!$B$2:$S$333,12,FALSE),"") | K21: =IFERROR(VLOOKUP($D21,Sheet1!$B$2:$S$333,14,FALSE),"") | L21: =IFERROR(VLOOKUP($D21,Sheet1!$B$2:$S$333,16,FALSE),"") | M21: =IFERROR(VLOOKUP($D21,Sheet1!$B$2:$S$333,18,FALSE),"")
F22: =_xlfn.IFNA(VLOOKUP($D22,Sheet1!$B$2:$E$333,4,FALSE),"") | G22: =IFERROR(VLOOKUP($D22,Sheet1!$B$2:$S$333,6,FALSE),"") | H22: =IFERROR(VLOOKUP($D22,Sheet1!$B$2:$S$333,8,FALSE),"") | I22: =IFERROR(VLOOKUP($D22,Sheet1!$B$2:$S$333,10,FALSE),"") | J22: =IFERROR(VLOOKUP($D22,Sheet1!$B$2:$S$333,12,FALSE),"") | K22: =IFERROR(VLOOKUP($D22,Sheet1!$B$2:$S$333,14,FALSE),"") | L22: =IFERROR(VLOOKUP($D22,Sheet1!$B$2:$S$333,16,FALSE),"") | M22: =IFERROR(VLOOKUP($D22,Sheet1!$B$2:$S$333,18,FALSE),"")
F23: =_xlfn.IFNA(VLOOKUP($D23,Sheet1!$B$2:$E$333,4,FALSE),"") | G23: =IFERROR(VLOOKUP($D23,Sheet1!$B$2:$S$333,6,FALSE),"") | H23: =IFERROR(VLOOKUP($D23,Sheet1!$B$2:$S$333,8,FALSE),"") | I23: =IFERROR(VLOOKUP($D23,Sheet1!$B$2:$S$333,10,FALSE),"") | J23: =IFERROR(VLOOKUP($D23,Sheet1!$B$2:$S$333,12,FALSE),"") | K23: =IFERROR(VLOOKUP($D23,Sheet1!$B$2:$S$333,14,FALSE),"") | L23: =IFERROR(VLOOKUP($D23,Sheet1!$B$2:$S$333,16,FALSE),"") | M23: =IFERROR(VLOOKUP($D23,Sheet1!$B$2:$S$333,18,FALSE),"")
F24: =_xlfn.IFNA(VLOOKUP($D24,Sheet1!$B$2:$E$333,4,FALSE),"") | G24: =IFERROR(VLOOKUP($D24,Sheet1!$B$2:$S$333,6,FALSE),"") | H24: =IFERROR(VLOOKUP($D24,Sheet1!$B$2:$S$333,8,FALSE),"") | I24: =IFERROR(VLOOKUP($D24,Sheet1!$B$2:$S$333,10,FALSE),"") | J24: =IFERROR(VLOOKUP($D24,Sheet1!$B$2:$S$333,12,FALSE),"") | K24: =IFERROR(VLOOKUP($D24,Sheet1!$B$2:$S$333,14,FALSE),"") | L24: =IFERROR(VLOOKUP($D24,Sheet1!$B$2:$S$333,16,FALSE),"") | M24: =IFERROR(VLOOKUP($D24,Sheet1!$B$2:$S$333,18,FALSE),"")
F25: =_xlfn.IFNA(VLOOKUP($D25,Sheet1!$B$2:$E$333,4,FALSE),"") | G25: =IFERROR(VLOOKUP($D25,Sheet1!$B$2:$S$333,6,FALSE),"") | H25: =IFERROR(VLOOKUP($D25,Sheet1!$B$2:$S$333,8,FALSE),"") | I25: =IFERROR(VLOOKUP($D25,Sheet1!$B$2:$S$333,10,FALSE),"") | J25: =IFERROR(VLOOKUP($D25,Sheet1!$B$2:$S$333,12,FALSE),"") | K25: =IFERROR(VLOOKUP($D25,Sheet1!$B$2:$S$333,14,FALSE),"") | L25: =IFERROR(VLOOKUP($D25,Sheet1!$B$2:$S$333,16,FALSE),"") | M25: =IFERROR(VLOOKUP($D25,Sheet1!$B$2:$S$333,18,FALSE),"") | U25: COASTAL - GAD
F26: =_xlfn.IFNA(VLOOKUP($D26,Sheet1!$B$2:$E$333,4,FALSE),"") | G26: =IFERROR(VLOOKUP($D26,Sheet1!$B$2:$S$333,6,FALSE),"") | H26: =IFERROR(VLOOKUP($D26,Sheet1!$B$2:$S$333,8,FALSE),"") | I26: =IFERROR(VLOOKUP($D26,Sheet1!$B$2:$S$333,10,FALSE),"") | J26: =IFERROR(VLOOKUP($D26,Sheet1!$B$2:$S$333,12,FALSE),"") | K26: =IFERROR(VLOOKUP($D26,Sheet1!$B$2:$S$333,14,FALSE),"") | L26: =IFERROR(VLOOKUP($D26,Sheet1!$B$2:$S$333,16,FALSE),"") | M26: =IFERROR(VLOOKUP($D26,Sheet1!$B$2:$S$333,18,FALSE),"") | U26: relief acd's
F27: =_xlfn.IFNA(VLOOKUP($D27,Sheet1!$B$2:$E$333,4,FALSE),"") | G27: =IFERROR(VLOOKUP($D27,Sheet1!$B$2:$S$333,6,FALSE),"") | H27: =IFERROR(VLOOKUP($D27,Sheet1!$B$2:$S$333,8,FALSE),"") | I27: =IFERROR(VLOOKUP($D27,Sheet1!$B$2:$S$333,10,FALSE),"") | J27: =IFERROR(VLOOKUP($D27,Sheet1!$B$2:$S$333,12,FALSE),"") | K27: =IFERROR(VLOOKUP($D27,Sheet1!$B$2:$S$333,14,FALSE),"") | L27: =IFERROR(VLOOKUP($D27,Sheet1!$B$2:$S$333,16,FALSE),"") | M27: =IFERROR(VLOOKUP($D27,Sheet1!$B$2:$S$333,18,FALSE),"")
C28: GREATLAKES
B29: DE, QC, MT | C29: {=_xlfn._xlws.FILTER(Sheet1!$A$2:$C$333,Sheet1!$C$2:$C$333='GAD DISPATCHER SCHEDULE'!$U$14)} -> BONNER, DEVIAN | D29: 1030404 | E29: GREATLAKES - GAD | F29: =_xlfn.IFNA(VLOOKUP($D29,Sheet1!$B$2:$E$333,4,FALSE),"") -> 0 | G29: =IFERROR(VLOOKUP($D29,Sheet1!$B$2:$S$333,6,FALSE),"") -> SA-1 | H29: =IFERROR(VLOOKUP($D29,Sheet1!$B$2:$S$333,8,FALSE),"") -> SA-2 | I29: =IFERROR(VLOOKUP($D29,Sheet1!$B$2:$S$333,10,FALSE),"") -> SA-2 | J29: =IFERROR(VLOOKUP($D29,Sheet1!$B$2:$S$333,12,FALSE),"") -> SA-3 | K29: =IFERROR(VLOOKUP($D29,Sheet1!$B$2:$S$333,14,FALSE),"") -> OFF | L29: =IFERROR(VLOOKUP($D29,Sheet1!$B$2:$S$333,16,FALSE),"") -> OFF | M29: =IFERROR(VLOOKUP($D29,Sheet1!$B$2:$S$333,18,FALSE),"") -> MT-3
B30: SA, MT, DE | C30: HESSELTINE, BRAEDEN | D30: 1024137 | E30: GREATLAKES - GAD | F30: =_xlfn.IFNA(VLOOKUP($D30,Sheet1!$B$2:$E$333,4,FALSE),"") -> 0 | G30: =IFERROR(VLOOKUP($D30,Sheet1!$B$2:$S$333,6,FALSE),"") -> LF-2 | H30: =IFERROR(VLOOKUP($D30,Sheet1!$B$2:$S$333,8,FALSE),"") -> LF-2 | I30: =IFERROR(VLOOKUP($D30,Sheet1!$B$2:$S$333,10,FALSE),"") -> CG-3 | J30: =IFERROR(VLOOKUP($D30,Sheet1!$B$2:$S$333,12,FALSE),"") -> AVAILABLE | K30: =IFERROR(VLOOKUP($D30,Sheet1!$B$2:$S$333,14,FALSE),"") -> OFF | L30: =IFERROR(VLOOKUP($D30,Sheet1!$B$2:$S$333,16,FALSE),"") -> OFF | M30: =IFERROR(VLOOKUP($D30,Sheet1!$B$2:$S$333,18,FALSE),"") -> LF-3
B31: DE, MT, CG, SA | C31: JOHNSON, EMILY | D31: 1014067 | E31: GREATLAKES - GAD | F31: =_xlfn.IFNA(VLOOKUP($D31,Sheet1!$B$2:$E$333,4,FALSE),"") -> 0 | G31: =IFERROR(VLOOKUP($D31,Sheet1!$B$2:$S$333,6,FALSE),"") -> TT-3 | H31: =IFERROR(VLOOKUP($D31,Sheet1!$B$2:$S$333,8,FALSE),"") -> TT-3 | I31: =IFERROR(VLOOKUP($D31,Sheet1!$B$2:$S$333,10,FALSE),"") -> OFF | J31: =IFERROR(VLOOKUP($D31,Sheet1!$B$2:$S$333,12,FALSE),"") -> OFF | K31: =IFERROR(VLOOKUP($D31,Sheet1!$B$2:$S$333,14,FALSE),"") -> EL-3 | L31: =IFERROR(VLOOKUP($D31,Sheet1!$B$2:$S$333,16,FALSE),"") -> S-SD | M31: =IFERROR(VLOOKUP($D31,Sheet1!$B$2:$S$333,18,FALSE),"") -> EL-3
B32: DT, EL, CD, CG DE | C32: MCGOLDRICK, MATT | D32: 1031115 | E32: GREATLAKES - GAD | F32: =_xlfn.IFNA(VLOOKUP($D32,Sheet1!$B$2:$E$333,4,FALSE),"") -> 0 | G32: =IFERROR(VLOOKUP($D32,Sheet1!$B$2:$S$333,6,FALSE),"") -> OFF | H32: =IFERROR(VLOOKUP($D32,Sheet1!$B$2:$S$333,8,FALSE),"") -> OFF | I32: =IFERROR(VLOOKUP($D32,Sheet1!$B$2:$S$333,10,FALSE),"") -> CD-2 | J32: =IFERROR(VLOOKUP($D32,Sheet1!$B$2:$S$333,12,FALSE),"") -> CD-3 | K32: =IFERROR(VLOOKUP($D32,Sheet1!$B$2:$S$333,14,FALSE),"") -> CD-3 | L32: =IFERROR(VLOOKUP($D32,Sheet1!$B$2:$S$333,16,FALSE),"") -> AVAILABLE | M32: =IFERROR(VLOOKUP($D32,Sheet1!$B$2:$S$333,18,FALSE),"") -> CD-1
B33: DT, CD, EL, | C33: MCINTYRE, SHAE | D33: 1028383 | E33: GREATLAKES - GAD | F33: =_xlfn.IFNA(VLOOKUP($D33,Sheet1!$B$2:$E$333,4,FALSE),"") -> 0 | G33: =IFERROR(VLOOKUP($D33,Sheet1!$B$2:$S$333,6,FALSE),"") -> FMLA | H33: =IFERROR(VLOOKUP($D33,Sheet1!$B$2:$S$333,8,FALSE),"") -> FMLA | I33: =IFERROR(VLOOKUP($D33,Sheet1!$B$2:$S$333,10,FALSE),"") -> FMLA | J33: =IFERROR(VLOOKUP($D33,Sheet1!$B$2:$S$333,12,FALSE),"") -> FMLA | K33: =IFERROR(VLOOKUP($D33,Sheet1!$B$2:$S$333,14,FALSE),"") -> FMLA | L33: =IFERROR(VLOOKUP($D33,Sheet1!$B$2:$S$333,16,FALSE),"") -> FMLA | M33: =IFERROR(VLOOKUP($D33,Sheet1!$B$2:$S$333,18,FALSE),"") -> FMLA
B34: PR, TE, DT, CG | C34: MIMS, CHRISTOPHER | D34: 1030366 | E34: GREATLAKES - GAD | F34: =_xlfn.IFNA(VLOOKUP($D34,Sheet1!$B$2:$E$333,4,FALSE),"") -> 0 | G34: =IFERROR(VLOOKUP($D34,Sheet1!$B$2:$S$333,6,FALSE),"") -> RL-3 | H34: =IFERROR(VLOOKUP($D34,Sheet1!$B$2:$S$333,8,FALSE),"") -> RL-3 | I34: =IFERROR(VLOOKUP($D34,Sheet1!$B$2:$S$333,10,FALSE),"") -> OFF | J34: =IFERROR(VLOOKUP($D34,Sheet1!$B$2:$S$333,12,FALSE),"") -> OFF | K34: =IFERROR(VLOOKUP($D34,Sheet1!$B$2:$S$333,14,FALSE),"") -> AVAILABLE | L34: =IFERROR(VLOOKUP($D34,Sheet1!$B$2:$S$333,16,FALSE),"") -> AVAILABLE | M34: =IFERROR(VLOOKUP($D34,Sheet1!$B$2:$S$333,18,FALSE),"") -> MT-2
C35: SLANEY, MATTHEW | D35: 1026431 | E35: GREATLAKES - GAD | F35: =_xlfn.IFNA(VLOOKUP($D35,Sheet1!$B$2:$E$333,4,FALSE),"") -> 0 | G35: =IFERROR(VLOOKUP($D35,Sheet1!$B$2:$S$333,6,FALSE),"") -> OFF | H35: =IFERROR(VLOOKUP($D35,Sheet1!$B$2:$S$333,8,FALSE),"") -> OFF | I35: =IFERROR(VLOOKUP($D35,Sheet1!$B$2:$S$333,10,FALSE),"") -> HE-1 | J35: =IFERROR(VLOOKUP($D35,Sheet1!$B$2:$S$333,12,FALSE),"") -> MV-1 | K35: =IFERROR(VLOOKUP($D35,Sheet1!$B$2:$S$333,14,FALSE),"") -> HE-3 | L35: =IFERROR(VLOOKUP($D35,Sheet1!$B$2:$S$333,16,FALSE),"") -> EL-3 | M35: =IFERROR(VLOOKUP($D35,Sheet1!$B$2:$S$333,18,FALSE),"") -> AVAILABLE
C36: TAYLOR, JASMINE | D36: 1026382 | E36: GREATLAKES - GAD | F36: =_xlfn.IFNA(VLOOKUP($D36,Sheet1!$B$2:$E$333,4,FALSE),"") -> 0 | G36: =IFERROR(VLOOKUP($D36,Sheet1!$B$2:$S$333,6,FALSE),"") -> OFF | H36: =IFERROR(VLOOKUP($D36,Sheet1!$B$2:$S$333,8,FALSE),"") -> KN-2 | I36: =IFERROR(VLOOKUP($D36,Sheet1!$B$2:$S$333,10,FALSE),"") -> SA-3 | J36: =IFERROR(VLOOKUP($D36,Sheet1!$B$2:$S$333,12,FALSE),"") -> KN-3 | K36: =IFERROR(VLOOKUP($D36,Sheet1!$B$2:$S$333,14,FALSE),"") -> SA-3 | L36: =IFERROR(VLOOKUP($D36,Sheet1!$B$2:$S$333,16,FALSE),"") -> AVAILABLE | M36: =IFERROR(VLOOKUP($D36,Sheet1!$B$2:$S$333,18,FALSE),"") -> SA-1
C37: WAGUESPACK, SAMMY | D37: 1025503 | E37: GREATLAKES - GAD | F37: =_xlfn.IFNA(VLOOKUP($D37,Sheet1!$B$2:$E$333,4,FALSE),"") -> 0 | G37: =IFERROR(VLOOKUP($D37,Sheet1!$B$2:$S$333,6,FALSE),"") -> CG-1 | H37: =IFERROR(VLOOKUP($D37,Sheet1!$B$2:$S$333,8,FALSE),"") -> SO-2 | I37: =IFERROR(VLOOKUP($D37,Sheet1!$B$2:$S$333,10,FALSE),"") -> TT-3 | J37: =IFERROR(VLOOKUP($D37,Sheet1!$B$2:$S$333,12,FALSE),"") -> TT-3 | K37: =IFERROR(VLOOKUP($D37,Sheet1!$B$2:$S$333,14,FALSE),"") -> OFF | L37: =IFERROR(VLOOKUP($D37,Sheet1!$B$2:$S$333,16,FALSE),"") -> OFF | M37: =IFERROR(VLOOKUP($D37,Sheet1!$B$2:$S$333,18,FALSE),"") -> MT-1-POST
F38: =_xlfn.IFNA(VLOOKUP($D38,Sheet1!$B$2:$E$333,4,FALSE),"") | G38: =IFERROR(VLOOKUP($D38,Sheet1!$B$2:$S$333,6,FALSE),"") | H38: =IFERROR(VLOOKUP($D38,Sheet1!$B$2:$S$333,8,FALSE),"") | I38: =IFERROR(VLOOKUP($D38,Sheet1!$B$2:$S$333,10,FALSE),"") | J38: =IFERROR(VLOOKUP($D38,Sheet1!$B$2:$S$333,12,FALSE),"") | K38: =IFERROR(VLOOKUP($D38,Sheet1!$B$2:$S$333,14,FALSE),"") | L38: =IFERROR(VLOOKUP($D38,Sheet1!$B$2:$S$333,16,FALSE),"") | M38: =IFERROR(VLOOKUP($D38,Sheet1!$B$2:$S$333,18,FALSE),"")
F39: =_xlfn.IFNA(VLOOKUP($D39,Sheet1!$B$2:$E$333,4,FALSE),"") | G39: =IFERROR(VLOOKUP($D39,Sheet1!$B$2:$S$333,6,FALSE),"") | H39: =IFERROR(VLOOKUP($D39,Sheet1!$B$2:$S$333,8,FALSE),"") | I39: =IFERROR(VLOOKUP($D39,Sheet1!$B$2:$S$333,10,FALSE),"") | J39: =IFERROR(VLOOKUP($D39,Sheet1!$B$2:$S$333,12,FALSE),"") | K39: =IFERROR(VLOOKUP($D39,Sheet1!$B$2:$S$333,14,FALSE),"") | L39: =IFERROR(VLOOKUP($D39,Sheet1!$B$2:$S$333,16,FALSE),"") | M39: =IFERROR(VLOOKUP($D39,Sheet1!$B$2:$S$333,18,FALSE),"")
F40: =_xlfn.IFNA(VLOOKUP($D40,Sheet1!$B$2:$E$333,4,FALSE),"") | G40: =IFERROR(VLOOKUP($D40,Sheet1!$B$2:$S$333,6,FALSE),"") | H40: =IFERROR(VLOOKUP($D40,Sheet1!$B$2:$S$333,8,FALSE),"") | I40: =IFERROR(VLOOKUP($D40,Sheet1!$B$2:$S$333,10,FALSE),"") | J40: =IFERROR(VLOOKUP($D40,Sheet1!$B$2:$S$333,12,FALSE),"") | K40: =IFERROR(VLOOKUP($D40,Sheet1!$B$2:$S$333,14,FALSE),"") | L40: =IFERROR(VLOOKUP($D40,Sheet1!$B$2:$S$333,16,FALSE),"") | M40: =IFERROR(VLOOKUP($D40,Sheet1!$B$2:$S$333,18,FALSE),"")
F41: =_xlfn.IFNA(VLOOKUP($D41,Sheet1!$B$2:$E$333,4,FALSE),"") | G41: =IFERROR(VLOOKUP($D41,Sheet1!$B$2:$S$333,6,FALSE),"") | H41: =IFERROR(VLOOKUP($D41,Sheet1!$B$2:$S$333,8,FALSE),"") | I41: =IFERROR(VLOOKUP($D41,Sheet1!$B$2:$S$333,10,FALSE),"") | J41: =IFERROR(VLOOKUP($D41,Sheet1!$B$2:$S$333,12,FALSE),"") | K41: =IFERROR(VLOOKUP($D41,Sheet1!$B$2:$S$333,14,FALSE),"") | L41: =IFERROR(VLOOKUP($D41,Sheet1!$B$2:$S$333,16,FALSE),"") | M41: =IFERROR(VLOOKUP($D41,Sheet1!$B$2:$S$333,18,FALSE),"")
F42: =_xlfn.IFNA(VLOOKUP($D42,Sheet1!$B$2:$E$333,4,FALSE),"") | G42: =IFERROR(VLOOKUP($D42,Sheet1!$B$2:$S$333,6,FALSE),"") | H42: =IFERROR(VLOOKUP($D42,Sheet1!$B$2:$S$333,8,FALSE),"") | I42: =IFERROR(VLOOKUP($D42,Sheet1!$B$2:$S$333,10,FALSE),"") | J42: =IFERROR(VLOOKUP($D42,Sheet1!$B$2:$S$333,12,FALSE),"") | K42: =IFERROR(VLOOKUP($D42,Sheet1!$B$2:$S$333,14,FALSE),"") | L42: =IFERROR(VLOOKUP($D42,Sheet1!$B$2:$S$333,16,FALSE),"") | M42: =IFERROR(VLOOKUP($D42,Sheet1!$B$2:$S$333,18,FALSE),"")
...

Sheet NORTHERN REGION SCHEDULE
F1: NORTHERN REGION NETWORK OPERATIONS CENTER DISPATCHER SCHEDULE
G4: =TEXT(G5,"dddd") -> Saturday | H4: =TEXT(H5,"dddd") -> Sunday | I4: =TEXT(I5,"dddd") -> Monday | J4: =TEXT(J5,"dddd") -> Tuesday | K4: =TEXT(K5,"dddd") -> Wednesday | L4: =TEXT(L5,"dddd") -> Thursday | M4: =TEXT(M5,"dddd") -> Friday
F5: DESK | G5: =Sheet1!F1 -> 45969 | H5: =+G5+1 -> 45970 | I5: =+H5+1 -> 45971 | J5: =+I5+1 -> 45972 | K5: =+J5+1 -> 45973 | L5: =+K5+1 -> 45974 | M5: =+L5+1 -> 45975
F6: KEYSTONE
C7: 1ST SHIFT | E7: HT-1 | F7: HT - HARRISBURG TERMINAL | G7: {=IF(RIGHT(_xlfn._xlws.FILTER(Sheet1!$G$2:$G$333,(Sheet1!$G$2:$G$333=$E7)+(Sheet1!$G$2:$G$333=$E8)+(Sheet1!$G$2:$G$333=$E9),""),4)="POST",CONCATENATE(_xlfn._xlws.FILTER(Sheet1!$A$2:$A$333,(Sheet1!$G$2:$G$333=$E7)+(Sheet1!$G$2:$G$333=$E8)+(Sheet1!$G$2:$G$333=$E9),""),"-","POST"),_xlfn._xlws.FILTER(Sheet1!$A$2:$A$333,(Sheet1!$G$2:$G$333=$E7)+(Sheet1!$G$2:$G$333=$E8)+(Sheet1!$G$2:$G$333=$E9),"UNFILLED"))} -> CLAFFY, DEIDRE | H7: {=IF(RIGHT(_xlfn._xlws.FILTER(Sheet1!$I$2:$I$333,(Sheet1!$I$2:$I$333=$E7)+(Sheet1!$I$2:$I$333=$E8)+(Sheet1!$I$2:$I$333=$E9),""),4)="POST",CONCATENATE(_xlfn._xlws.FILTER(Sheet1!$A$2:$A$333,(Sheet1!$I$2:$I$333=$E7)+(Sheet1!$I$2:$I$333=$E8)+(Sheet1!$I$2:$I$333=$E9),""),"-","POST"),_xlfn._xlws.FILTER(Sheet1!$A$2:$A$333,(Sheet1!$I$2:$I$333=$E7)+(Sheet1!$I$2:$I$333=$E8)+(Sheet1!$I$2:$I$333=$E9),"UNFILLED"))} -> CAMARDA, CHRIS | I7: {=IF(RIGHT(_xlfn._xlws.FILTER(Sheet1!$K$2:$K$333,(Sheet1!$K$2:$K$333=$E7)+(Sheet1!$K$2:$K$333=$E8)+(Sheet1!$K$2:$K$333=$E9),""),4)="POST",CONCATENATE(_xlfn._xlws.FILTER(Sheet1!$A$2:$A$333,(Sheet1!$K$2:$K$333=$E7)+(Sheet1!$K$2:$K$333=$E8)+(Sheet1!$K$2:$K$333=$E9),""),"-","POST"),_xlfn._xlws.FILTER(Sheet1!$A$2:$A$333,(Sheet1!$K$2:$K$333=$E7)+(Sheet1!$K$2:$K$333=$E8)+(Sheet1!$K$2:$K$333=$E9),"UNFILLED"))} -> CAMARDA, CHRIS | J7: {=IF(RIGHT(_xlfn._xlws.FILTER(Sheet1!M$2:M$333,(Sheet1!M$2:M$333=$E7)+(Sheet1!M$2:M$333=$E8)+(Sheet1!M$2:M$333=$E9),""),4)="POST",CONCATENATE(_xlfn._xlws.FILTER(Sheet1!$A$2:$A$333,(Sheet1!M$2:M$333=$E7)+(Sheet1!M$2:M$333=$E8)+(Sheet1!M$2:M$333=$E9),""),"-","POST"),_xlfn._xlws.FILTER(Sheet1!$A$2:$A$333,(Sheet1!M$2:M$333=$E7)+(Sheet1!M$2:M$333=$E8)+(Sheet1!M$2:M$333=$E9),"UNFILLED"))} -> CAMARDA, CHRIS | K7: {=IF(RIGHT(_xlfn._xlws.FILTER(Sheet1!$O$2:$O$333,(Sheet1!$O$2:$O$333=$E7)+(Sheet1!$O$2:$O$333=$E8)+(Sheet1!$O$2:$O$333=$E9),""),4)="POST",CONCATENATE(_xlfn._xlws.FILTER(Sheet1!$A$2:$A$333,(Sheet1!$O$2:$O$333=$E7)+(Sheet1!$O$2:$O$333=$E8)+(Sheet1!$O$2:$O$333=$E9),""),"-","POST"),_xlfn._xlws.FILTER(Sheet1!$A$2:$A$333,(Sheet1!$O$2:$O$333=$E7)+(Sheet1!$O$2:$O$333=$E8)+(Sheet1!$O$2:$O$333=$E9),"UNFILLED"))} -> CAMARDA, CHRIS | L7: {=IF(RIGHT(_xlfn._xlws.FILTER(Sheet1!$Q$2:$Q$333,(Sheet1!$Q$2:$Q$333=$E7)+(Sheet1!$Q$2:$Q$333=$E8)+(Sheet1!$Q$2:$Q$333=$E9),""),4)="POST",CONCATENATE(_xlfn._xlws.FILTER(Sheet1!$A$2:$A$333,(Sheet1!$Q$2:$Q$333=$E7)+(Sheet1!$Q$2:$Q$333=$E8)+(Sheet1!$Q$2:$Q$333=$E9),""),"-","POST"),_xlfn._xlws.FILTER(Sheet1!$A$2:$A$333,(Sheet1!$Q$2:$Q$333=$E7)+(Sheet1!$Q$2:$Q$333=$E8)+(Sheet1!$Q$2:$Q$333=$E9),"UNFILLED"))} -> CAMARDA, CHRIS | M7: {=IF(RIGHT(_xlfn._xlws.FILTER(Sheet1!$S$2:$S$333,(Sheet1!$S$2:$S$333=$E7)+(Sheet1!$S$2:$S$333=$E8)+(Sheet1!$S$2:$S$333=$E9),""),4)="POST",CONCATENATE(_xlfn._xlws.FILTER(Sheet1!$A$2:$A$333,(Sheet1!$S$2:$S$333=$E7)+(Sheet1!$S$2:$S$333=$E8)+(Sheet1!$S$2:$S$333=$E9),""),"-","POST"),_xlfn._xlws.FILTER(Sheet1!$A$2:$A$333,(Sheet1!$S$2:$S$333=$E7)+(Sheet1!$S$2:$S$333=$E8)+(Sheet1!$S$2:$S$333=$E9),"UNFILLED"))} -> CLAFFY, DEIDRE
E8: =_xlfn.CONCAT(E7,"-","POST") -> HT-1-POST
E9: =_xlfn.CONCAT(E7,"-","PILOT") -> HT-1-PILOT
E10: HE-1 | F10: HE - HARRISBURG EAST | G10: {=IF(RIGHT(_xlfn._xlws.FILTER(Sheet1!$G$2:$G$333,(Sheet1!$G$2:$G$333=$E10)+(Sheet1!$G$2:$G$333=$E11)+(Sheet1!$G$2:$G$333=$E12),""),4)="POST",CONCATENATE(_xlfn._xlws.FILTER(Sheet1!$A$2:$A$333,(Sheet1!$G$2:$G$333=$E10)+(Sheet1!$G$2:$G$333=$E11)+(Sheet1!$G$2:$G$333=$E12),""),"-","POST"),_xlfn._xlws.FILTER(Sheet1!$A$2:$A$333,(Sheet1!$G$2:$G$333=$E10)+(Sheet1!$G$2:$G$333=$E11)+(Sheet1!$G$2:$G$333=$E12),"UNFILLED"))} -> JONES, ANTHONY | H10: {=IF(RIGHT(_xlfn._xlws.FILTER(Sheet1!$I$2:$I$333,(Sheet1!$I$2:$I$333=$E10)+(Sheet1!$I$2:$I$333=$E11)+(Sheet1!$I$2:$I$333=$E12),""),4)="POST",CONCATENATE(_xlfn._xlws.FILTER(Sheet1!$A$2:$A$333,(Sheet1!$I$2:$I$333=$E10)+(Sheet1!$I$2:$I$333=$E11)+(Sheet1!$I$2:$I$333=$E12),""),"-","POST"),_xlfn._xlws.FILTER(Sheet1!$A$2:$A$333,(Sheet1!$I$2:$I$333=$E10)+(Sheet1!$I$2:$I$333=$E11)+(Sheet1!$I$2:$I$333=$E12),"UNFILLED"))} -> TUCKER, JUSTIN | I10: {=IF(RIGHT(_xlfn._xlws.FILTER(Sheet1!$K$2:$K$333,(Sheet1!$K$2:$K$333=$E10)+(Sheet1!$K$2:$K$333=$E11)+(Sheet1!$K$2:$K$333=$E12),""),4)="POST",CONCATENATE(_xlfn._xlws.FILTER(Sheet1!$A$2:$A$333,(Sheet1!$K$2:$K$333=$E10)+(Sheet1!$K$2:$K$333=$E11)+(Sheet1!$K$2:$K$333=$E12),""),"-","POST"),_xlfn._xlws.FILTER(Sheet1!$A$2:$A$333,(Sheet1!$K$2:$K$333=$E10)+(Sheet1!$K$2:$K$333=$E11)+(Sheet1!$K$2:$K$333=$E12),"UNFILLED"))} -> SLANEY, MATTHEW | J10: {=IF(RIGHT(_xlfn._xlws.FILTER(Sheet1!M$2:M$333,(Sheet1!M$2:M$333=$E10)+(Sheet1!M$2:M$333=$E11)+(Sheet1!M$2:M$333=$E12),""),4)="POST",CONCATENATE(_xlfn._xlws.FILTER(Sheet1!$A$2:$A$333,(Sheet1!M$2:M$333=$E10)+(Sheet1!M$2:M$333=$E11)+(Sheet1!M$2:M$333=$E12),""),"-","POST"),_xlfn._xlws.FILTER(Sheet1!$A$2:$A$333,(Sheet1!M$2:M$333=$E10)+(Sheet1!M$2:M$333=$E11)+(Sheet1!M$2:M$333=$E12),"UNFILLED"))} -> CARR, JEREMY | K10: {=IF(RIGHT(_xlfn._xlws.FILTER(Sheet1!$O$2:$O$333,(Sheet1!$O$2:$O$333=$E10)+(Sheet1!$O$2:$O$333=$E11)+(Sheet1!$O$2:$O$333=$E12),""),4)="POST",CONCATENATE(_xlfn._xlws.FILTER(Sheet1!$A$2:$A$333,(Sheet1!$O$2:$O$333=$E10)+(Sheet1!$O$2:$O$333=$E11)+(Sheet1!$O$2:$O$333=$E12),""),"-","POST"),_xlfn._xlws.FILTER(Sheet1!$A$2:$A$333,(Sheet1!$O$2:$O$333=$E10)+(Sheet1!$O$2:$O$333=$E11)+(Sheet1!$O$2:$O$333=$E12),"UNFILLED"))} -> CARR, JEREMY | L10: {=IF(RIGHT(_xlfn._xlws.FILTER(Sheet1!$Q$2:$Q$333,(Sheet1!$Q$2:$Q$333=$E10)+(Sheet1!$Q$2:$Q$333=$E11)+(Sheet1!$Q$2:$Q$333=$E12),""),4)="POST",CONCATENATE(_xlfn._xlws.FILTER(Sheet1!$A$2:$A$333,(Sheet1!$Q$2:$Q$333=$E10)+(Sheet1!$Q$2:$Q$333=$E11)+(Sheet1!$Q$2:$Q$333=$E12),""),"-","POST"),_xlfn._xlws.FILTER(Sheet1!$A$2:$A$333,(Sheet1!$Q$2:$Q$333=$E10)+(Sheet1!$Q$2:$Q$333=$E11)+(Sheet1!$Q$2:$Q$333=$E12),"UNFILLED"))} -> CARR, JEREMY | M10: {=IF(RIGHT(_xlfn._xlws.FILTER(Sheet1!$S$2:$S$333,(Sheet1!$S$2:$S$333=$E10)+(Sheet1!$S$2:$S$333=$E11)+(Sheet1!$S$2:$S$333=$E12),""),4)="POST",CONCATENATE(_xlfn._xlws.FILTER(Sheet1!$A$2:$A$333,(Sheet1!$S$2:$S$333=$E10)+(Sheet1!$S$2:$S$333=$E11)+(Sheet1!$S$2:$S$333=$E12),""),"-","POST"),_xlfn._xlws.FILTER(Sheet1!$A$2:$A$333,(Sheet1!$S$2:$S$333=$E10)+(Sheet1!$S$2:$S$333=$E11)+(Sheet1!$S$2:$S$333=$E12),"UNFILLED"))} -> CARR, JEREMY
E11: =_xlfn.CONCAT(E10,"-","POST") -> HE-1-POST
E12: =_xlfn.CONCAT(E10,"-","PILOT") -> HE-1-PILOT
E13: RL-1 | F13: RL - RIVERLINE | G13: {=IF(RIGHT(_xlfn._xlws.FILTER(Sheet1!$G$2:$G$333,(Sheet1!$G$2:$G$333=$E13)+(Sheet1!$G$2:$G$333=$E14)+(Sheet1!$G$2:$G$333=$E15),""),4)="POST",CONCATENATE(_xlfn._xlws.FILTER(Sheet1!$A$2:$A$333,(Sheet1!$G$2:$G$333=$E13)+(Sheet1!$G$2:$G$333=$E14)+(Sheet1!$G$2:$G$333=$E15),""),"-","POST"),_xlfn._xlws.FILTER(Sheet1!$A$2:$A$333,(Sheet1!$G$2:$G$333=$E13)+(Sheet1!$G$2:$G$333=$E14)+(Sheet1!$G$2:$G$333=$E15),"UNFILLED"))} -> BOYD, MIA | H13: {=IF(RIGHT(_xlfn._xlws.FILTER(Sheet1!$I$2:$I$333,(Sheet1!$I$2:$I$333=$E13)+(Sheet1!$I$2:$I$333=$E14)+(Sheet1!$I$2:$I$333=$E15),""),4)="POST",CONCATENATE(_xlfn._xlws.FILTER(Sheet1!$A$2:$A$333,(Sheet1!$I$2:$I$333=$E13)+(Sheet1!$I$2:$I$333=$E14)+(Sheet1!$I$2:$I$333=$E15),""),"-","POST"),_xlfn._xlws.FILTER(Sheet1!$A$2:$A$333,(Sheet1!$I$2:$I$333=$E13)+(Sheet1!$I$2:$I$333=$E14)+(Sheet1!$I$2:$I$333=$E15),"UNFILLED"))} -> ROTH, KATE | I13: {=IF(RIGHT(_xlfn._xlws.FILTER(Sheet1!$K$2:$K$333,(Sheet1!$K$2:$K$333=$E13)+(Sheet1!$K$2:$K$333=$E14)+(Sheet1!$K$2:$K$333=$E15),""),4)="POST",CONCATENATE(_xlfn._xlws.FILTER(Sheet1!$A$2:$A$333,(Sheet1!$K$2:$K$333=$E13)+(Sheet1!$K$2:$K$333=$E14)+(Sheet1!$K$2:$K$333=$E15),""),"-","POST"),_xlfn._xlws.FILTER(Sheet1!$A$2:$A$333,(Sheet1!$K$2:$K$333=$E13)+(Sheet1!$K$2:$K$333=$E14)+(Sheet1!$K$2:$K$333=$E15),"UNFILLED"))} -> ROTH, KATE | J13: {=IF(RIGHT(_xlfn._xlws.FILTER(Sheet1!M$2:M$333,(Sheet1!M$2:M$333=$E13)+(Sheet1!M$2:M$333=$E14)+(Sheet1!M$2:M$333=$E15),""),4)="POST",CONCATENATE(_xlfn._xlws.FILTER(Sheet1!$A$2:$A$333,(Sheet1!M$2:M$333=$E13)+(Sheet1!M$2:M$333=$E14)+(Sheet1!M$2:M$333=$E15),""),"-","POST"),_xlfn._xlws.FILTER(Sheet1!$A$2:$A$333,(Sheet1!M$2:M$333=$E13)+(Sheet1!M$2:M$333=$E14)+(Sheet1!M$2:M$333=$E15),"UNFILLED"))} -> ROTH, KATE | K13: {=IF(RIGHT(_xlfn._xlws.FILTER(Sheet1!$O$2:$O$333,(Sheet1!$O$2:$O$333=$E13)+(Sheet1!$O$2:$O$333=$E14)+(Sheet1!$O$2:$O$333=$E15),""),4)="POST",CONCATENATE(_xlfn._xlws.FILTER(Sheet1!$A$2:$A$333,(Sheet1!$O$2:$O$333=$E13)+(Sheet1!$O$2:$O$333=$E14)+(Sheet1!$O$2:$O$333=$E15),""),"-","POST"),_xlfn._xlws.FILTER(Sheet1!$A$2:$A$333,(Sheet1!$O$2:$O$333=$E13)+(Sheet1!$O$2:$O$333=$E14)+(Sheet1!$O$2:$O$333=$E15),"UNFILLED"))} -> ROTH, KATE | L13: {=IF(RIGHT(_xlfn._xlws.FILTER(Sheet1!$Q$2:$Q$333,(Sheet1!$Q$2:$Q$333=$E13)+(Sheet1!$Q$2:$Q$333=$E14)+(Sheet1!$Q$2:$Q$333=$E15),""),4)="POST",CONCATENATE(_xlfn._xlws.FILTER(Sheet1!$A$2:$A$333,(Sheet1!$Q$2:$Q$333=$E13)+(Sheet1!$Q$2:$Q$333=$E14)+(Sheet1!$Q$2:$Q$333=$E15),""),"-","POST"),_xlfn._xlws.FILTER(Sheet1!$A$2:$A$333,(Sheet1!$Q$2:$Q$333=$E13)+(Sheet1!$Q$2:$Q$333=$E14)+(Sheet1!$Q$2:$Q$333=$E15),"UNFILLED"))} -> ROTH, KATE | M13: {=IF(RIGHT(_xlfn._xlws.FILTER(Sheet1!$S$2:$S$333,(Sheet1!$S$2:$S$333=$E13)+(Sheet1!$S$2:$S$333=$E14)+(Sheet1!$S$2:$S$333=$E15),""),4)="POST",CONCATENATE(_xlfn._xlws.FILTER(Sheet1!$A$2:$A$333,(Sheet1!$S$2:$S$333=$E13)+(Sheet1!$S$2:$S$333=$E14)+(Sheet1!$S$2:$S$333=$E15),""),"-","POST"),_xlfn._xlws.FILTER(Sheet1!$A$2:$A$333,(Sheet1!$S$2:$S$333=$E13)+(Sheet1!$S$2:$S$333=$E14)+(Sheet1!$S$2:$S$333=$E15),"UNFILLED"))} -> BOYD, MIA
E14: =_xlfn.CONCAT(E13,"-","POST") -> RL-1-POST | G14: TUCKER, JUSTIN-POST
E15: =_xlfn.CONCAT(E13,"-","PILOT") -> RL-1-PILOT
E16: DH-1 | F16: DH - D & H | G16: {=IF(RIGHT(_xlfn._xlws.FILTER(Sheet1!$G$2:$G$333,(Sheet1!$G$2:$G$333=$E16)+(Sheet1!$G$2:$G$333=$E17)+(Sheet1!$G$2:$G$333=$E18),""),4)="POST",CONCATENATE(_xlfn._xlws.FILTER(Sheet1!$A$2:$A$333,(Sheet1!$G$2:$G$333=$E16)+(Sheet1!$G$2:$G$333=$E17)+(Sheet1!$G$2:$G$333=$E18),""),"-","POST"),_xlfn._xlws.FILTER(Sheet1!$A$2:$A$333,(Sheet1!$G$2:$G$333=$E16)+(Sheet1!$G$2:$G$333=$E17)+(Sheet1!$G$2:$G$333=$E18),"UNFILLED"))} -> ZEIGLER, KIMBERLY | H16: {=IF(RIGHT(_xlfn._xlws.FILTER(Sheet1!$I$2:$I$333,(Sheet1!$I$2:$I$333=$E16)+(Sheet1!$I$2:$I$333=$E17)+(Sheet1!$I$2:$I$333=$E18),""),4)="POST",CONCATENATE(_xlfn._xlws.FILTER(Sheet1!$A$2:$A$333,(Sheet1!$I$2:$I$333=$E16)+(Sheet1!$I$2:$I$333=$E17)+(Sheet1!$I$2:$I$333=$E18),""),"-","POST"),_xlfn._xlws.FILTER(Sheet1!$A$2:$A$333,(Sheet1!$I$2:$I$333=$E16)+(Sheet1!$I$2:$I$333=$E17)+(Sheet1!$I$2:$I$333=$E18),"UNFILLED"))} -> ZEIGLER, KIMBERLY | I16: {=IF(RIGHT(_xlfn._xlws.FILTER(Sheet1!$K$2:$K$333,(Sheet1!$K$2:$K$333=$E16)+(Sheet1!$K$2:$K$333=$E17)+(Sheet1!$K$2:$K$333=$E18),""),4)="POST",CONCATENATE(_xlfn._xlws.FILTER(Sheet1!$A$2:$A$333,(Sheet1!$K$2:$K$333=$E16)+(Sheet1!$K$2:$K$333=$E17)+(Sheet1!$K$2:$K$333=$E18),""),"-","POST"),_xlfn._xlws.FILTER(Sheet1!$A$2:$A$333,(Sheet1!$K$2:$K$333=$E16)+(Sheet1!$K$2:$K$333=$E17)+(Sheet1!$K$2:$K$333=$E18),"UNFILLED"))} -> WIMMER, CHRISTOPHER | J16: {=IF(RIGHT(_xlfn._xlws.FILTER(Sheet1!M$2:M$333,(Sheet1!M$2:M$333=$E16)+(Sheet1!M$2:M$333=$E17)+(Sheet1!M$2:M$333=$E18),""),4)="POST",CONCATENATE(_xlfn._xlws.FILTER(Sheet1!$A$2:$A$333,(Sheet1!M$2:M$333=$E16)+(Sheet1!M$2:M$333=$E17)+(Sheet1!M$2:M$333=$E18),""),"-","POST"),_xlfn._xlws.FILTER(Sheet1!$A$2:$A$333,(Sheet1!M$2:M$333=$E16)+(Sheet1!M$2:M$333=$E17)+(Sheet1!M$2:M$333=$E18),"UNFILLED"))} -> WIMMER, CHRISTOPHER | K16: {=IF(RIGHT(_xlfn._xlws.FILTER(Sheet1!$O$2:$O$333,(Sheet1!$O$2:$O$333=$E16)+(Sheet1!$O$2:$O$333=$E17)+(Sheet1!$O$2:$O$333=$E18),""),4)="POST",CONCATENATE(_xlfn._xlws.FILTER(Sheet1!$A$2:$A$333,(Sheet1!$O$2:$O$333=$E16)+(Sheet1!$O$2:$O$333=$E17)+(Sheet1!$O$2:$O$333=$E18),""),"-","POST"),_xlfn._xlws.FILTER(Sheet1!$A$2:$A$333,(Sheet1!$O$2:$O$333=$E16)+(Sheet1!$O$2:$O$333=$E17)+(Sheet1!$O$2:$O$333=$E18),"UNFILLED"))} -> WIMMER, CHRISTOPHER | L16: {=IF(RIGHT(_xlfn._xlws.FILTER(Sheet1!$Q$2:$Q$333,(Sheet1!$Q$2:$Q$333=$E16)+(Sheet1!$Q$2:$Q$333=$E17)+(Sheet1!$Q$2:$Q$333=$E18),""),4)="POST",CONCATENATE(_xlfn._xlws.FILTER(Sheet1!$A$2:$A$333,(Sheet1!$Q$2:$Q$333=$E16)+(Sheet1!$Q$2:$Q$333=$E17)+(Sheet1!$Q$2:$Q$333=$E18),""),"-","POST"),_xlfn._xlws.FILTER(Sheet1!$A$2:$A$333,(Sheet1!$Q$2:$Q$333=$E16)+(Sheet1!$Q$2:$Q$333=$E17)+(Sheet1!$Q$2:$Q$333=$E18),"UNFILLED"))} -> WIMMER, CHRISTOPHER | M16: {=IF(RIGHT(_xlfn._xlws.FILTER(Sheet1!$S$2:$S$333,(Sheet1!$S$2:$S$333=$E16)+(Sheet1!$S$2:$S$333=$E17)+(Sheet1!$S$2:$S$333=$E18),""),4)="POST",CONCATENATE(_xlfn._xlws.FILTER(Sheet1!$A$2:$A$333,(Sheet1!$S$2:$S$333=$E16)+(Sheet1!$S$2:$S$333=$E17)+(Sheet1!$S$2:$S$333=$E18),""),"-","POST"),_xlfn._xlws.FILTER(Sheet1!$A$2:$A$333,(Sheet1!$S$2:$S$333=$E16)+(Sheet1!$S$2:$S$333=$E17)+(Sheet1!$S$2:$S$333=$E18),"UNFILLED"))} -> WIMMER, CHRISTOPHER
E17: =_xlfn.CONCAT(E16,"-","POST") -> DH-1-POST
E18: =_xlfn.CONCAT(E16,"-","PILOT") -> DH-1-PILOT
E19: AL-1 | F19: AL - ALLEGHENY | G19: {=IF(RIGHT(_xlfn._xlws.FILTER(Sheet1!$G$2:$G$333,(Sheet1!$G$2:$G$333=$E19)+(Sheet1!$G$2:$G$333=$E20)+(Sheet1!$G$2:$G$333=$E21),""),4)="POST",CONCATENATE(_xlfn._xlws.FILTER(Sheet1!$A$2:$A$333,(Sheet1!$G$2:$G$333=$E19)+(Sheet1!$G$2:$G$333=$E20)+(Sheet1!$G$2:$G$333=$E21),""),"-","POST"),_xlfn._xlws.FILTER(Sheet1!$A$2:$A$333,(Sheet1!$G$2:$G$333=$E19)+(Sheet1!$G$2:$G$333=$E20)+(Sheet1!$G$2:$G$333=$E21),"UNFILLED"))} -> PANELLA, MICHAEL | H19: {=IF(RIGHT(_xlfn._xlws.FILTER(Sheet1!$I$2:$I$333,(Sheet1!$I$2:$I$333=$E19)+(Sheet1!$I$2:$I$333=$E20)+(Sheet1!$I$2:$I$333=$E21),""),4)="POST",CONCATENATE(_xlfn._xlws.FILTER(Sheet1!$A$2:$A$333,(Sheet1!$I$2:$I$333=$E19)+(Sheet1!$I$2:$I$333=$E20)+(Sheet1!$I$2:$I$333=$E21),""),"-","POST"),_xlfn._xlws.FILTER(Sheet1!$A$2:$A$333,(Sheet1!$I$2:$I$333=$E19)+(Sheet1!$I$2:$I$333=$E20)+(Sheet1!$I$2:$I$333=$E21),"UNFILLED"))} -> PIFER, BRIAN | I19: {=IF(RIGHT(_xlfn._xlws.FILTER(Sheet1!$K$2:$K$333,(Sheet1!$K$2:$K$333=$E19)+(Sheet1!$K$2:$K$333=$E20)+(Sheet1!$K$2:$K$333=$E21),""),4)="POST",CONCATENATE(_xlfn._xlws.FILTER(Sheet1!$A$2:$A$333,(Sheet1!$K$2:$K$333=$E19)+(Sheet1!$K$2:$K$333=$E20)+(Sheet1!$K$2:$K$333=$E21),""),"-","POST"),_xlfn._xlws.FILTER(Sheet1!$A$2:$A$333,(Sheet1!$K$2:$K$333=$E19)+(Sheet1!$K$2:$K$333=$E20)+(Sheet1!$K$2:$K$333=$E21),"UNFILLED"))} -> PIFER, BRIAN | J19: {=IF(RIGHT(_xlfn._xlws.FILTER(Sheet1!M$2:M$333,(Sheet1!M$2:M$333=$E19)+(Sheet1!M$2:M$333=$E20)+(Sheet1!M$2:M$333=$E21),""),4)="POST",CONCATENATE(_xlfn._xlws.FILTER(Sheet1!$A$2:$A$333,(Sheet1!M$2:M$333=$E19)+(Sheet1!M$2:M$333=$E20)+(Sheet1!M$2:M$333=$E21),""),"-","POST"),_xlfn._xlws.FILTER(Sheet1!$A$2:$A$333,(Sheet1!M$2:M$333=$E19)+(Sheet1!M$2:M$333=$E20)+(Sheet1!M$2:M$333=$E21),"UNFILLED"))} -> THOMAS, FRANK | K19: {=IF(RIGHT(_xlfn._xlws.FILTER(Sheet1!$O$2:$O$333,(Sheet1!$O$2:$O$333=$E19)+(Sheet1!$O$2:$O$333=$E20)+(Sheet1!$O$2:$O$333=$E21),""),4)="POST",CONCATENATE(_xlfn._xlws.FILTER(Sheet1!$A$2:$A$333,(Sheet1!$O$2:$O$333=$E19)+(Sheet1!$O$2:$O$333=$E20)+(Sheet1!$O$2:$O$333=$E21),""),"-","POST"),_xlfn._xlws.FILTER(Sheet1!$A$2:$A$333,(Sheet1!$O$2:$O$333=$E19)+(Sheet1!$O$2:$O$333=$E20)+(Sheet1!$O$2:$O$333=$E21),"UNFILLED"))} -> TUCKER, JUSTIN | L19: {=IF(RIGHT(_xlfn._xlws.FILTER(Sheet1!$Q$2:$Q$333,(Sheet1!$Q$2:$Q$333=$E19)+(Sheet1!$Q$2:$Q$333=$E20)+(Sheet1!$Q$2:$Q$333=$E21),""),4)="POST",CONCATENATE(_xlfn._xlws.FILTER(Sheet1!$A$2:$A$333,(Sheet1!$Q$2:$Q$333=$E19)+(Sheet1!$Q$2:$Q$333=$E20)+(Sheet1!$Q$2:$Q$333=$E21),""),"-","POST"),_xlfn._xlws.FILTER(Sheet1!$A$2:$A$333,(Sheet1!$Q$2:$Q$333=$E19)+(Sheet1!$Q$2:$Q$333=$E20)+(Sheet1!$Q$2:$Q$333=$E21),"UNFILLED"))} -> TUCKER, JUSTIN | M19: {=IF(RIGHT(_xlfn._xlws.FILTER(Sheet1!$S$2:$S$333,(Sheet1!$S$2:$S$333=$E19)+(Sheet1!$S$2:$S$333=$E20)+(Sheet1!$S$2:$S$333=$E21),""),4)="POST",CONCATENATE(_xlfn._xlws.FILTER(Sheet1!$A$2:$A$333,(Sheet1!$S$2:$S$333=$E19)+(Sheet1!$S$2:$S$333=$E20)+(Sheet1!$S$2:$S$333=$E21),""),"-","POST"),_xlfn._xlws.FILTER(Sheet1!$A$2:$A$333,(Sheet1!$S$2:$S$333=$E19)+(Sheet1!$S$2:$S$333=$E20)+(Sheet1!$S$2:$S$333=$E21),"UNFILLED"))} -> PANELLA, MICHAEL
E20: =_xlfn.CONCAT(E19,"-","POST") -> AL-1-POST
E21: =_xlfn.CONCAT(E19,"-","PILOT") -> AL-1-PILOT
E22: CT-1 | F22: CT - CONWAY TERMINAL | G22: {=IF(RIGHT(_xlfn._xlws.FILTER(Sheet1!$G$2:$G$333,(Sheet1!$G$2:$G$333=$E22)+(Sheet1!$G$2:$G$333=$E23)+(Sheet1!$G$2:$G$333=$E24),""),4)="POST",CONCATENATE(_xlfn._xlws.FILTER(Sheet1!$A$2:$A$333,(Sheet1!$G$2:$G$333=$E22)+(Sheet1!$G$2:$G$333=$E23)+(Sheet1!$G$2:$G$333=$E24),""),"-","POST"),_xlfn._xlws.FILTER(Sheet1!$A$2:$A$333,(Sheet1!$G$2:$G$333=$E22)+(Sheet1!$G$2:$G$333=$E23)+(Sheet1!$G$2:$G$333=$E24),"UNFILLED"))} -> REYNOLDS, RO | H22: {=IF(RIGHT(_xlfn._xlws.FILTER(Sheet1!$I$2:$I$333,(Sheet1!$I$2:$I$333=$E22)+(Sheet1!$I$2:$I$333=$E23)+(Sheet1!$I$2:$I$333=$E24),""),4)="POST",CONCATENATE(_xlfn._xlws.FILTER(Sheet1!$A$2:$A$333,(Sheet1!$I$2:$I$333=$E22)+(Sheet1!$I$2:$I$333=$E23)+(Sheet1!$I$2:$I$333=$E24),""),"-","POST"),_xlfn._xlws.FILTER(Sheet1!$A$2:$A$333,(Sheet1!$I$2:$I$333=$E22)+(Sheet1!$I$2:$I$333=$E23)+(Sheet1!$I$2:$I$333=$E24),"UNFILLED"))} -> REYNOLDS, RO | I22: {=IF(RIGHT(_xlfn._xlws.FILTER(Sheet1!$K$2:$K$333,(Sheet1!$K$2:$K$333=$E22)+(Sheet1!$K$2:$K$333=$E23)+(Sheet1!$K$2:$K$333=$E24),""),4)="POST",CONCATENATE(_xlfn._xlws.FILTER(Sheet1!$A$2:$A$333,(Sheet1!$K$2:$K$333=$E22)+(Sheet1!$K$2:$K$333=$E23)+(Sheet1!$K$2:$K$333=$E24),""),"-","POST"),_xlfn._xlws.FILTER(Sheet1!$A$2:$A$333,(Sheet1!$K$2:$K$333=$E22)+(Sheet1!$K$2:$K$333=$E23)+(Sheet1!$K$2:$K$333=$E24),"UNFILLED"))} -> GEE, ASHLEY-POST | J22: {=IF(RIGHT(_xlfn._xlws.FILTER(Sheet1!M$2:M$333,(Sheet1!M$2:M$333=$E22)+(Sheet1!M$2:M$333=$E23)+(Sheet1!M$2:M$333=$E24),""),4)="POST",CONCATENATE(_xlfn._xlws.FILTER(Sheet1!$A$2:$A$333,(Sheet1!M$2:M$333=$E22)+(Sheet1!M$2:M$333=$E23)+(Sheet1!M$2:M$333=$E24),""),"-","POST"),_xlfn._xlws.FILTER(Sheet1!$A$2:$A$333,(Sheet1!M$2:M$333=$E22)+(Sheet1!M$2:M$333=$E23)+(Sheet1!M$2:M$333=$E24),"UNFILLED"))} -> GEE, ASHLEY-POST | K22: {=IF(RIGHT(_xlfn._xlws.FILTER(Sheet1!$O$2:$O$333,(Sheet1!$O$2:$O$333=$E22)+(Sheet1!$O$2:$O$333=$E23)+(Sheet1!$O$2:$O$333=$E24),""),4)="POST",CONCATENATE(_xlfn._xlws.FILTER(Sheet1!$A$2:$A$333,(Sheet1!$O$2:$O$333=$E22)+(Sheet1!$O$2:$O$333=$E23)+(Sheet1!$O$2:$O$333=$E24),""),"-","POST"),_xlfn._xlws.FILTER(Sheet1!$A$2:$A$333,(Sheet1!$O$2:$O$333=$E22)+(Sheet1!$O$2:$O$333=$E23)+(Sheet1!$O$2:$O$333=$E24),"UNFILLED"))} -> GEE, ASHLEY-POST | L22: {=IF(RIGHT(_xlfn._xlws.FILTER(Sheet1!$Q$2:$Q$333,(Sheet1!$Q$2:$Q$333=$E22)+(Sheet1!$Q$2:$Q$333=$E23)+(Sheet1!$Q$2:$Q$333=$E24),""),4)="POST",CONCATENATE(_xlfn._xlws.FILTER(Sheet1!$A$2:$A$333,(Sheet1!$Q$2:$Q$333=$E22)+(Sheet1!$Q$2:$Q$333=$E23)+(Sheet1!$Q$2:$Q$333=$E24),""),"-","POST"),_xlfn._xlws.FILTER(Sheet1!$A$2:$A$333,(Sheet1!$Q$2:$Q$333=$E22)+(Sheet1!$Q$2:$Q$333=$E23)+(Sheet1!$Q$2:$Q$333=$E24),"UNFILLED"))} -> GEE, ASHLEY-POST | M22: {=IF(RIGHT(_xlfn._xlws.FILTER(Sheet1!$S$2:$S$333,(Sheet1!$S$2:$S$333=$E22)+(Sheet1!$S$2:$S$333=$E23)+(Sheet1!$S$2:$S$333=$E24),""),4)="POST",CONCATENATE(_xlfn._xlws.FILTER(Sheet1!$A$2:$A$333,(Sheet1!$S$2:$S$333=$E22)+(Sheet1!$S$2:$S$333=$E23)+(Sheet1!$S$2:$S$333=$E24),""),"-","POST"),_xlfn._xlws.FILTER(Sheet1!$A$2:$A$333,(Sheet1!$S$2:$S$333=$E22)+(Sheet1!$S$2:$S$333=$E23)+(Sheet1!$S$2:$S$333=$E24),"UNFILLED"))} -> GEE, ASHLEY-POST
E23: =_xlfn.CONCAT(E22,"-","POST") -> CT-1-POST | I23: RITCHIE, MIKE | J23: HARP, KEENAN | K23: RITCHIE, MIKE | L23: RITCHIE, MIKE | M23: RITCHIE, MIKE
E24: =_xlfn.CONCAT(E22,"-","PILOT") -> CT-1-PILOT
E25: PE-1 | F25: PE - PITTSBURGH EAST | G25: {=IF(RIGHT(_xlfn._xlws.FILTER(Sheet1!$G$2:$G$333,(Sheet1!$G$2:$G$333=$E25)+(Sheet1!$G$2:$G$333=$E26)+(Sheet1!$G$2:$G$333=$E27),""),4)="POST",CONCATENATE(_xlfn._xlws.FILTER(Sheet1!$A$2:$A$333,(Sheet1!$G$2:$G$333=$E25)+(Sheet1!$G$2:$G$333=$E26)+(Sheet1!$G$2:$G$333=$E27),""),"-","POST"),_xlfn._xlws.FILTER(Sheet1!$A$2:$A$333,(Sheet1!$G$2:$G$333=$E25)+(Sheet1!$G$2:$G$333=$E26)+(Sheet1!$G$2:$G$333=$E27),"UNFILLED"))} -> FERGUSON, CRAIG | H25: {=IF(RIGHT(_xlfn._xlws.FILTER(Sheet1!$I$2:$I$333,(Sheet1!$I$2:$I$333=$E25)+(Sheet1!$I$2:$I$333=$E26)+(Sheet1!$I$2:$I$333=$E27),""),4)="POST",CONCATENATE(_xlfn._xlws.FILTER(Sheet1!$A$2:$A$333,(Sheet1!$I$2:$I$333=$E25)+(Sheet1!$I$2:$I$333=$E26)+(Sheet1!$I$2:$I$333=$E27),""),"-","POST"),_xlfn._xlws.FILTER(Sheet1!$A$2:$A$333,(Sheet1!$I$2:$I$333=$E25)+(Sheet1!$I$2:$I$333=$E26)+(Sheet1!$I$2:$I$333=$E27),"UNFILLED"))} -> LUTERAN, COREY | I25: {=IF(RIGHT(_xlfn._xlws.FILTER(Sheet1!$K$2:$K$333,(Sheet1!$K$2:$K$333=$E25)+(Sheet1!$K$2:$K$333=$E26)+(Sheet1!$K$2:$K$333=$E27),""),4)="POST",CONCATENATE(_xlfn._xlws.FILTER(Sheet1!$A$2:$A$333,(Sheet1!$K$2:$K$333=$E25)+(Sheet1!$K$2:$K$333=$E26)+(Sheet1!$K$2:$K$333=$E27),""),"-","POST"),_xlfn._xlws.FILTER(Sheet1!$A$2:$A$333,(Sheet1!$K$2:$K$333=$E25)+(Sheet1!$K$2:$K$333=$E26)+(Sheet1!$K$2:$K$333=$E27),"UNFILLED"))} -> LUTERAN, COREY | J25: {=IF(RIGHT(_xlfn._xlws.FILTER(Sheet1!M$2:M$333,(Sheet1!M$2:M$333=$E25)+(Sheet1!M$2:M$333=$E26)+(Sheet1!M$2:M$333=$E27),""),4)="POST",CONCATENATE(_xlfn._xlws.FILTER(Sheet1!$A$2:$A$333,(Sheet1!M$2:M$333=$E25)+(Sheet1!M$2:M$333=$E26)+(Sheet1!M$2:M$333=$E27),""),"-","POST"),_xlfn._xlws.FILTER(Sheet1!$A$2:$A$333,(Sheet1!M$2:M$333=$E25)+(Sheet1!M$2:M$333=$E26)+(Sheet1!M$2:M$333=$E27),"UNFILLED"))} -> LUTERAN, COREY | K25: {=IF(RIGHT(_xlfn._xlws.FILTER(Sheet1!$O$2:$O$333,(Sheet1!$O$2:$O$333=$E25)+(Sheet1!$O$2:$O$333=$E26)+(Sheet1!$O$2:$O$333=$E27),""),4)="POST",CONCATENATE(_xlfn._xlws.FILTER(Sheet1!$A$2:$A$333,(Sheet1!$O$2:$O$333=$E25)+(Sheet1!$O$2:$O$333=$E26)+(Sheet1!$O$2:$O$333=$E27),""),"-","POST"),_xlfn._xlws.FILTER(Sheet1!$A$2:$A$333,(Sheet1!$O$2:$O$333=$E25)+(Sheet1!$O$2:$O$333=$E26)+(Sheet1!$O$2:$O$333=$E27),"UNFILLED"))} -> LUTERAN, COREY | L25: {=IF(RIGHT(_xlfn._xlws.FILTER(Sheet1!$Q$2:$Q$333,(Sheet1!$Q$2:$Q$333=$E25)+(Sheet1!$Q$2:$Q$333=$E26)+(Sheet1!$Q$2:$Q$333=$E27),""),4)="POST",CONCATENATE(_xlfn._xlws.FILTER(Sheet1!$A$2:$A$333,(Sheet1!$Q$2:$Q$333=$E25)+(Sheet1!$Q$2:$Q$333=$E26)+(Sheet1!$Q$2:$Q$333=$E27),""),"-","POST"),_xlfn._xlws.FILTER(Sheet1!$A$2:$A$333,(Sheet1!$Q$2:$Q$333=$E25)+(Sheet1!$Q$2:$Q$333=$E26)+(Sheet1!$Q$2:$Q$333=$E27),"UNFILLED"))} -> LUTERAN, COREY | M25: {=IF(RIGHT(_xlfn._xlws.FILTER(Sheet1!$S$2:$S$333,(Sheet1!$S$2:$S$333=$E25)+(Sheet1!$S$2:$S$333=$E26)+(Sheet1!$S$2:$S$333=$E27),""),4)="POST",CONCATENATE(_xlfn._xlws.FILTER(Sheet1!$A$2:$A$333,(Sheet1!$S$2:$S$333=$E25)+(Sheet1!$S$2:$S$333=$E26)+(Sheet1!$S$2:$S$333=$E27),""),"-","POST"),_xlfn._xlws.FILTER(Sheet1!$A$2:$A$333,(Sheet1!$S$2:$S$333=$E25)+(Sheet1!$S$2:$S$333=$E26)+(Sheet1!$S$2:$S$333=$E27),"UNFILLED"))} -> MALCOLM, JOSH
E26: =_xlfn.CONCAT(E25,"-","POST") -> PE-1-POST
E27: =_xlfn.CONCAT(E25,"-","PILOT") -> PE-1-PILOT
E28: MV-1 | F28: MV - MON VALLEY | G28: {=IF(RIGHT(_xlfn._xlws.FILTER(Sheet1!$G$2:$G$333,(Sheet1!$G$2:$G$333=$E28)+(Sheet1!$G$2:$G$333=$E29)+(Sheet1!$G$2:$G$333=$E30),""),4)="POST",CONCATENATE(_xlfn._xlws.FILTER(Sheet1!$A$2:$A$333,(Sheet1!$G$2:$G$333=$E28)+(Sheet1!$G$2:$G$333=$E29)+(Sheet1!$G$2:$G$333=$E30),""),"-","POST"),_xlfn._xlws.FILTER(Sheet1!$A$2:$A$333,(Sheet1!$G$2:$G$333=$E28)+(Sheet1!$G$2:$G$333=$E29)+(Sheet1!$G$2:$G$333=$E30),"UNFILLED"))} -> BAUMAN, BRENT | H28: {=IF(RIGHT(_xlfn._xlws.FILTER(Sheet1!$I$2:$I$333,(Sheet1!$I$2:$I$333=$E28)+(Sheet1!$I$2:$I$333=$E29)+(Sheet1!$I$2:$I$333=$E30),""),4)="POST",CONCATENATE(_xlfn._xlws.FILTER(Sheet1!$A$2:$A$333,(Sheet1!$I$2:$I$333=$E28)+(Sheet1!$I$2:$I$333=$E29)+(Sheet1!$I$2:$I$333=$E30),""),"-","POST"),_xlfn._xlws.FILTER(Sheet1!$A$2:$A$333,(Sheet1!$I$2:$I$333=$E28)+(Sheet1!$I$2:$I$333=$E29)+(Sheet1!$I$2:$I$333=$E30),"UNFILLED"))} -> BAUMAN, BRENT | I28: {=IF(RIGHT(_xlfn._xlws.FILTER(Sheet1!$K$2:$K$333,(Sheet1!$K$2:$K$333=$E28)+(Sheet1!$K$2:$K$333=$E29)+(Sheet1!$K$2:$K$333=$E30),""),4)="POST",CONCATENATE(_xlfn._xlws.FILTER(Sheet1!$A$2:$A$333,(Sheet1!$K$2:$K$333=$E28)+(Sheet1!$K$2:$K$333=$E29)+(Sheet1!$K$2:$K$333=$E30),""),"-","POST"),_xlfn._xlws.FILTER(Sheet1!$A$2:$A$333,(Sheet1!$K$2:$K$333=$E28)+(Sheet1!$K$2:$K$333=$E29)+(Sheet1!$K$2:$K$333=$E30),"UNFILLED"))} -> HARP, KEENAN | J28: {=IF(RIGHT(_xlfn._xlws.FILTER(Sheet1!M$2:M$333,(Sheet1!M$2:M$333=$E28)+(Sheet1!M$2:M$333=$E29)+(Sheet1!M$2:M$333=$E30),""),4)="POST",CONCATENATE(_xlfn._xlws.FILTER(Sheet1!$A$2:$A$333,(Sheet1!M$2:M$333=$E28)+(Sheet1!M$2:M$333=$E29)+(Sheet1!M$2:M$333=$E30),""),"-","POST"),_xlfn._xlws.FILTER(Sheet1!$A$2:$A$333,(Sheet1!M$2:M$333=$E28)+(Sheet1!M$2:M$333=$E29)+(Sheet1!M$2:M$333=$E30),"UNFILLED"))} -> SLANEY, MATTHEW | K28: {=IF(RIGHT(_xlfn._xlws.FILTER(Sheet1!$O$2:$O$333,(Sheet1!$O$2:$O$333=$E28)+(Sheet1!$O$2:$O$333=$E29)+(Sheet1!$O$2:$O$333=$E30),""),4)="POST",CONCATENATE(_xlfn._xlws.FILTER(Sheet1!$A$2:$A$333,(Sheet1!$O$2:$O$333=$E28)+(Sheet1!$O$2:$O$333=$E29)+(Sheet1!$O$2:$O$333=$E30),""),"-","POST"),_xlfn._xlws.FILTER(Sheet1!$A$2:$A$333,(Sheet1!$O$2:$O$333=$E28)+(Sheet1!$O$2:$O$333=$E29)+(Sheet1!$O$2:$O$333=$E30),"UNFILLED"))} -> BAUMAN, BRENT | L28: {=IF(RIGHT(_xlfn._xlws.FILTER(Sheet1!$Q$2:$Q$333,(Sheet1!$Q$2:$Q$333=$E28)+(Sheet1!$Q$2:$Q$333=$E29)+(Sheet1!$Q$2:$Q$333=$E30),""),4)="POST",CONCATENATE(_xlfn._xlws.FILTER(Sheet1!$A$2:$A$333,(Sheet1!$Q$2:$Q$333=$E28)+(Sheet1!$Q$2:$Q$333=$E29)+(Sheet1!$Q$2:$Q$333=$E30),""),"-","POST"),_xlfn._xlws.FILTER(Sheet1!$A$2:$A$333,(Sheet1!$Q$2:$Q$333=$E28)+(Sheet1!$Q$2:$Q$333=$E29)+(Sheet1!$Q$2:$Q$333=$E30),"UNFILLED"))} -> BAUMAN, BRENT | M28: {=IF(RIGHT(_xlfn._xlws.FILTER(Sheet1!$S$2:$S$333,(Sheet1!$S$2:$S$333=$E28)+(Sheet1!$S$2:$S$333=$E29)+(Sheet1!$S$2:$S$333=$E30),""),4)="POST",CONCATENATE(_xlfn._xlws.FILTER(Sheet1!$A$2:$A$333,(Sheet1!$S$2:$S$333=$E28)+(Sheet1!$S$2:$S$333=$E29)+(Sheet1!$S$2:$S$333=$E30),""),"-","POST"),_xlfn._xlws.FILTER(Sheet1!$A$2:$A$333,(Sheet1!$S$2:$S$333=$E28)+(Sheet1!$S$2:$S$333=$E29)+(Sheet1!$S$2:$S$333=$E30),"UNFILLED"))} -> BAUMAN, BRENT
E29: =_xlfn.CONCAT(E28,"-","POST") -> MV-1-POST
E30: =_xlfn.CONCAT(E28,"-","PILOT") -> MV-1-PILOT
E31: CE-1 | F31: CE - CLEVELAND EAST | G31: {=IF(RIGHT(_xlfn._xlws.FILTER(Sheet1!$G$2:$G$333,(Sheet1!$G$2:$G$333=$E31)+(Sheet1!$G$2:$G$333=$E32)+(Sheet1!$G$2:$G$333=$E33),""),4)="POST",CONCATENATE(_xlfn._xlws.FILTER(Sheet1!$A$2:$A$333,(Sheet1!$G$2:$G$333=$E31)+(Sheet1!$G$2:$G$333=$E32)+(Sheet1!$G$2:$G$333=$E33),""),"-","POST"),_xlfn._xlws.FILTER(Sheet1!$A$2:$A$333,(Sheet1!$G$2:$G$333=$E31)+(Sheet1!$G$2:$G$333=$E32)+(Sheet1!$G$2:$G$333=$E33),"UNFILLED"))} -> FLEITES, FRANK | H31: {=IF(RIGHT(_xlfn._xlws.FILTER(Sheet1!$I$2:$I$333,(Sheet1!$I$2:$I$333=$E31)+(Sheet1!$I$2:$I$333=$E32)+(Sheet1!$I$2:$I$333=$E33),""),4)="POST",CONCATENATE(_xlfn._xlws.FILTER(Sheet1!$A$2:$A$333,(Sheet1!$I$2:$I$333=$E31)+(Sheet1!$I$2:$I$333=$E32)+(Sheet1!$I$2:$I$333=$E33),""),"-","POST"),_xlfn._xlws.FILTER(Sheet1!$A$2:$A$333,(Sheet1!$I$2:$I$333=$E31)+(Sheet1!$I$2:$I$333=$E32)+(Sheet1!$I$2:$I$333=$E33),"UNFILLED"))} -> FLEITES, FRANK | I31: {=IF(RIGHT(_xlfn._xlws.FILTER(Sheet1!$K$2:$K$333,(Sheet1!$K$2:$K$333=$E31)+(Sheet1!$K$2:$K$333=$E32)+(Sheet1!$K$2:$K$333=$E33),""),4)="POST",CONCATENATE(_xlfn._xlws.FILTER(Sheet1!$A$2:$A$333,(Sheet1!$K$2:$K$333=$E31)+(Sheet1!$K$2:$K$333=$E32)+(Sheet1!$K$2:$K$333=$E33),""),"-","POST"),_xlfn._xlws.FILTER(Sheet1!$A$2:$A$333,(Sheet1!$K$2:$K$333=$E31)+(Sheet1!$K$2:$K$333=$E32)+(Sheet1!$K$2:$K$333=$E33),"UNFILLED"))} -> DEJESUS, DAVE | J31: {=IF(RIGHT(_xlfn._xlws.FILTER(Sheet1!M$2:M$333,(Sheet1!M$2:M$333=$E31)+(Sheet1!M$2:M$333=$E32)+(Sheet1!M$2:M$333=$E33),""),4)="POST",CONCATENATE(_xlfn._xlws.FILTER(Sheet1!$A$2:$A$333,(Sheet1!M$2:M$333=$E31)+(Sheet1!M$2:M$333=$E32)+(Sheet1!M$2:M$333=$E33),""),"-","POST"),_xlfn._xlws.FILTER(Sheet1!$A$2:$A$333,(Sheet1!M$2:M$333=$E31)+(Sheet1!M$2:M$333=$E32)+(Sheet1!M$2:M$333=$E33),"UNFILLED"))} -> DEJESUS, DAVE | K31: {=IF(RIGHT(_xlfn._xlws.FILTER(Sheet1!$O$2:$O$333,(Sheet1!$O$2:$O$333=$E31)+(Sheet1!$O$2:$O$333=$E32)+(Sheet1!$O$2:$O$333=$E33),""),4)="POST",CONCATENATE(_xlfn._xlws.FILTER(Sheet1!$A$2:$A$333,(Sheet1!$O$2:$O$333=$E31)+(Sheet1!$O$2:$O$333=$E32)+(Sheet1!$O$2:$O$333=$E33),""),"-","POST"),_xlfn._xlws.FILTER(Sheet1!$A$2:$A$333,(Sheet1!$O$2:$O$333=$E31)+(Sheet1!$O$2:$O$333=$E32)+(Sheet1!$O$2:$O$333=$E33),"UNFILLED"))} -> DEJESUS, DAVE | L31: {=IF(RIGHT(_xlfn._xlws.FILTER(Sheet1!$Q$2:$Q$333,(Sheet1!$Q$2:$Q$333=$E31)+(Sheet1!$Q$2:$Q$333=$E32)+(Sheet1!$Q$2:$Q$333=$E33),""),4)="POST",CONCATENATE(_xlfn._xlws.FILTER(Sheet1!$A$2:$A$333,(Sheet1!$Q$2:$Q$333=$E31)+(Sheet1!$Q$2:$Q$333=$E32)+(Sheet1!$Q$2:$Q$333=$E33),""),"-","POST"),_xlfn._xlws.FILTER(Sheet1!$A$2:$A$333,(Sheet1!$Q$2:$Q$333=$E31)+(Sheet1!$Q$2:$Q$333=$E32)+(Sheet1!$Q$2:$Q$333=$E33),"UNFILLED"))} -> DEJESUS, DAVE | M31: {=IF(RIGHT(_xlfn._xlws.FILTER(Sheet1!$S$2:$S$333,(Sheet1!$S$2:$S$333=$E31)+(Sheet1!$S$2:$S$333=$E32)+(Sheet1!$S$2:$S$333=$E33),""),4)="POST",CONCATENATE(_xlfn._xlws.FILTER(Sheet1!$A$2:$A$333,(Sheet1!$S$2:$S$333=$E31)+(Sheet1!$S$2:$S$333=$E32)+(Sheet1!$S$2:$S$333=$E33),""),"-","POST"),_xlfn._xlws.FILTER(Sheet1!$A$2:$A$333,(Sheet1!$S$2:$S$333=$E31)+(Sheet1!$S$2:$S$333=$E32)+(Sheet1!$S$2:$S$333=$E33),"UNFILLED"))} -> DEJESUS, DAVE
E32: =_xlfn.CONCAT(E31,"-","POST") -> CE-1-POST
E33: =_xlfn.CONCAT(E31,"-","PILOT") -> CE-1-PILOT
F34: GREATLAKES
E35: CD-1 | F35: CD - CHICAGO TERMINAL | G35: {=IF(RIGHT(_xlfn._xlws.FILTER(Sheet1!$G$2:$G$333,(Sheet1!$G$2:$G$333=$E35)+(Sheet1!$G$2:$G$333=$E36)+(Sheet1!$G$2:$G$333=$E37),""),4)="POST",CONCATENATE(_xlfn._xlws.FILTER(Sheet1!$A$2:$A$333,(Sheet1!$G$2:$G$333=$E35)+(Sheet1!$G$2:$G$333=$E36)+(Sheet1!$G$2:$G$333=$E37),""),"-","POST"),_xlfn._xlws.FILTER(Sheet1!$A$2:$A$333,(Sheet1!$G$2:$G$333=$E35)+(Sheet1!$G$2:$G$333=$E36)+(Sheet1!$G$2:$G$333=$E37),"UNFILLED"))} -> BOUCHARD, SHARLIE | H35: {=IF(RIGHT(_xlfn._xlws.FILTER(Sheet1!$I$2:$I$333,(Sheet1!$I$2:$I$333=$E35)+(Sheet1!$I$2:$I$333=$E36)+(Sheet1!$I$2:$I$333=$E37),""),4)="POST",CONCATENATE(_xlfn._xlws.FILTER(Sheet1!$A$2:$A$333,(Sheet1!$I$2:$I$333=$E35)+(Sheet1!$I$2:$I$333=$E36)+(Sheet1!$I$2:$I$333=$E37),""),"-","POST"),_xlfn._xlws.FILTER(Sheet1!$A$2:$A$333,(Sheet1!$I$2:$I$333=$E35)+(Sheet1!$I$2:$I$333=$E36)+(Sheet1!$I$2:$I$333=$E37),"UNFILLED"))} -> CLUBBS, DARIN | I35: {=IF(RIGHT(_xlfn._xlws.FILTER(Sheet1!$K$2:$K$333,(Sheet1!$K$2:$K$333=$E35)+(Sheet1!$K$2:$K$333=$E36)+(Sheet1!$K$2:$K$333=$E37),""),4)="POST",CONCATENATE(_xlfn._xlws.FILTER(Sheet1!$A$2:$A$333,(Sheet1!$K$2:$K$333=$E35)+(Sheet1!$K$2:$K$333=$E36)+(Sheet1!$K$2:$K$333=$E37),""),"-","POST"),_xlfn._xlws.FILTER(Sheet1!$A$2:$A$333,(Sheet1!$K$2:$K$333=$E35)+(Sheet1!$K$2:$K$333=$E36)+(Sheet1!$K$2:$K$333=$E37),"UNFILLED"))} -> CLUBBS, DARIN | J35: {=IF(RIGHT(_xlfn._xlws.FILTER(Sheet1!M$2:M$333,(Sheet1!M$2:M$333=$E35)+(Sheet1!M$2:M$333=$E36)+(Sheet1!M$2:M$333=$E37),""),4)="POST",CONCATENATE(_xlfn._xlws.FILTER(Sheet1!$A$2:$A$333,(Sheet1!M$2:M$333=$E35)+(Sheet1!M$2:M$333=$E36)+(Sheet1!M$2:M$333=$E37),""),"-","POST"),_xlfn._xlws.FILTER(Sheet1!$A$2:$A$333,(Sheet1!M$2:M$333=$E35)+(Sheet1!M$2:M$333=$E36)+(Sheet1!M$2:M$333=$E37),"UNFILLED"))} -> CLUBBS, DARIN | K35: {=IF(RIGHT(_xlfn._xlws.FILTER(Sheet1!$O$2:$O$333,(Sheet1!$O$2:$O$333=$E35)+(Sheet1!$O$2:$O$333=$E36)+(Sheet1!$O$2:$O$333=$E37),""),4)="POST",CONCATENATE(_xlfn._xlws.FILTER(Sheet1!$A$2:$A$333,(Sheet1!$O$2:$O$333=$E35)+(Sheet1!$O$2:$O$333=$E36)+(Sheet1!$O$2:$O$333=$E37),""),"-","POST"),_xlfn._xlws.FILTER(Sheet1!$A$2:$A$333,(Sheet1!$O$2:$O$333=$E35)+(Sheet1!$O$2:$O$333=$E36)+(Sheet1!$O$2:$O$333=$E37),"UNFILLED"))} -> CLUBBS, DARIN | L35: {=IF(RIGHT(_xlfn._xlws.FILTER(Sheet1!$Q$2:$Q$333,(Sheet1!$Q$2:$Q$333=$E35)+(Sheet1!$Q$2:$Q$333=$E36)+(Sheet1!$Q$2:$Q$333=$E37),""),4)="POST",CONCATENATE(_xlfn._xlws.FILTER(Sheet1!$A$2:$A$333,(Sheet1!$Q$2:$Q$333=$E35)+(Sheet1!$Q$2:$Q$333=$E36)+(Sheet1!$Q$2:$Q$333=$E37),""),"-","POST"),_xlfn._xlws.FILTER(Sheet1!$A$2:$A$333,(Sheet1!$Q$2:$Q$333=$E35)+(Sheet1!$Q$2:$Q$333=$E36)+(Sheet1!$Q$2:$Q$333=$E37),"UNFILLED"))} -> CLUBBS, DARIN | M35: {=IF(RIGHT(_xlfn._xlws.FILTER(Sheet1!$S$2:$S$333,(Sheet1!$S$2:$S$333=$E35)+(Sheet1!$S$2:$S$333=$E36)+(Sheet1!$S$2:$S$333=$E37),""),4)="POST",CONCATENATE(_xlfn._xlws.FILTER(Sheet1!$A$2:$A$333,(Sheet1!$S$2:$S$333=$E35)+(Sheet1!$S$2:$S$333=$E36)+(Sheet1!$S$2:$S$333=$E37),""),"-","POST"),_xlfn._xlws.FILTER(Sheet1!$A$2:$A$333,(Sheet1!$S$2:$S$333=$E35)+(Sheet1!$S$2:$S$333=$E36)+(Sheet1!$S$2:$S$333=$E37),"UNFILLED"))} -> MCGOLDRICK, MATT
E36: =_xlfn.CONCAT(E35,"-","POST") -> CD-1-POST
E37: =_xlfn.CONCAT(E35,"-","PILOT") -> CD-1-PILOT
E38: EL-1 | F38: EL - ELKHART | G38: {=IF(RIGHT(_xlfn._xlws.FILTER(Sheet1!$G$2:$G$333,(Sheet1!$G$2:$G$333=$E38)+(Sheet1!$G$2:$G$333=$E39)+(Sheet1!$G$2:$G$333=$E40),""),4)="POST",CONCATENATE(_xlfn._xlws.FILTER(Sheet1!$A$2:$A$333,(Sheet1!$G$2:$G$333=$E38)+(Sheet1!$G$2:$G$333=$E39)+(Sheet1!$G$2:$G$333=$E40),""),"-","POST"),_xlfn._xlws.FILTER(Sheet1!$A$2:$A$333,(Sheet1!$G$2:$G$333=$E38)+(Sheet1!$G$2:$G$333=$E39)+(Sheet1!$G$2:$G$333=$E40),"UNFILLED"))} -> ROBERTS, KIRVIN | H38: {=IF(RIGHT(_xlfn._xlws.FILTER(Sheet1!$I$2:$I$333,(Sheet1!$I$2:$I$333=$E38)+(Sheet1!$I$2:$I$333=$E39)+(Sheet1!$I$2:$I$333=$E40),""),4)="POST",CONCATENATE(_xlfn._xlws.FILTER(Sheet1!$A$2:$A$333,(Sheet1!$I$2:$I$333=$E38)+(Sheet1!$I$2:$I$333=$E39)+(Sheet1!$I$2:$I$333=$E40),""),"-","POST"),_xlfn._xlws.FILTER(Sheet1!$A$2:$A$333,(Sheet1!$I$2:$I$333=$E38)+(Sheet1!$I$2:$I$333=$E39)+(Sheet1!$I$2:$I$333=$E40),"UNFILLED"))} -> ROBERTS, KIRVIN | I38: {=IF(RIGHT(_xlfn._xlws.FILTER(Sheet1!$K$2:$K$333,(Sheet1!$K$2:$K$333=$E38)+(Sheet1!$K$2:$K$333=$E39)+(Sheet1!$K$2:$K$333=$E40),""),4)="POST",CONCATENATE(_xlfn._xlws.FILTER(Sheet1!$A$2:$A$333,(Sheet1!$K$2:$K$333=$E38)+(Sheet1!$K$2:$K$333=$E39)+(Sheet1!$K$2:$K$333=$E40),""),"-","POST"),_xlfn._xlws.FILTER(Sheet1!$A$2:$A$333,(Sheet1!$K$2:$K$333=$E38)+(Sheet1!$K$2:$K$333=$E39)+(Sheet1!$K$2:$K$333=$E40),"UNFILLED"))} -> NEGLEY, ANTHONY | J38: {=IF(RIGHT(_xlfn._xlws.FILTER(Sheet1!M$2:M$333,(Sheet1!M$2:M$333=$E38)+(Sheet1!M$2:M$333=$E39)+(Sheet1!M$2:M$333=$E40),""),4)="POST",CONCATENATE(_xlfn._xlws.FILTER(Sheet1!$A$2:$A$333,(Sheet1!M$2:M$333=$E38)+(Sheet1!M$2:M$333=$E39)+(Sheet1!M$2:M$333=$E40),""),"-","POST"),_xlfn._xlws.FILTER(Sheet1!$A$2:$A$333,(Sheet1!M$2:M$333=$E38)+(Sheet1!M$2:M$333=$E39)+(Sheet1!M$2:M$333=$E40),"UNFILLED"))} -> NEGLEY, ANTHONY | K38: {=IF(RIGHT(_xlfn._xlws.FILTER(Sheet1!$O$2:$O$333,(Sheet1!$O$2:$O$333=$E38)+(Sheet1!$O$2:$O$333=$E39)+(Sheet1!$O$2:$O$333=$E40),""),4)="POST",CONCATENATE(_xlfn._xlws.FILTER(Sheet1!$A$2:$A$333,(Sheet1!$O$2:$O$333=$E38)+(Sheet1!$O$2:$O$333=$E39)+(Sheet1!$O$2:$O$333=$E40),""),"-","POST"),_xlfn._xlws.FILTER(Sheet1!$A$2:$A$333,(Sheet1!$O$2:$O$333=$E38)+(Sheet1!$O$2:$O$333=$E39)+(Sheet1!$O$2:$O$333=$E40),"UNFILLED"))} -> NEGLEY, ANTHONY | L38: {=IF(RIGHT(_xlfn._xlws.FILTER(Sheet1!$Q$2:$Q$333,(Sheet1!$Q$2:$Q$333=$E38)+(Sheet1!$Q$2:$Q$333=$E39)+(Sheet1!$Q$2:$Q$333=$E40),""),4)="POST",CONCATENATE(_xlfn._xlws.FILTER(Sheet1!$A$2:$A$333,(Sheet1!$Q$2:$Q$333=$E38)+(Sheet1!$Q$2:$Q$333=$E39)+(Sheet1!$Q$2:$Q$333=$E40),""),"-","POST"),_xlfn._xlws.FILTER(Sheet1!$A$2:$A$333,(Sheet1!$Q$2:$Q$333=$E38)+(Sheet1!$Q$2:$Q$333=$E39)+(Sheet1!$Q$2:$Q$333=$E40),"UNFILLED"))} -> NEGLEY, ANTHONY | M38: {=IF(RIGHT(_xlfn._xlws.FILTER(Sheet1!$S$2:$S$333,(Sheet1!$S$2:$S$333=$E38)+(Sheet1!$S$2:$S$333=$E39)+(Sheet1!$S$2:$S$333=$E40),""),4)="POST",CONCATENATE(_xlfn._xlws.FILTER(Sheet1!$A$2:$A$333,(Sheet1!$S$2:$S$333=$E38)+(Sheet1!$S$2:$S$333=$E39)+(Sheet1!$S$2:$S$333=$E40),""),"-","POST"),_xlfn._xlws.FILTER(Sheet1!$A$2:$A$333,(Sheet1!$S$2:$S$333=$E38)+(Sheet1!$S$2:$S$333=$E39)+(Sheet1!$S$2:$S$333=$E40),"UNFILLED"))} -> NEGLEY, ANTHONY
E39: =_xlfn.CONCAT(E38,"-","POST") -> EL-1-POST
E40: =_xlfn.CONCAT(E38,"-","PILOT") -> EL-1-PILOT
E41: TT-1 | F41: TT - TOLEDO TERMINAL | G41: {=IF(RIGHT(_xlfn._xlws.FILTER(Sheet1!$G$2:$G$333,(Sheet1!$G$2:$G$333=$E41)+(Sheet1!$G$2:$G$333=$E42)+(Sheet1!$G$2:$G$333=$E43),""),4)="POST",CONCATENATE(_xlfn._xlws.FILTER(Sheet1!$A$2:$A$333,(Sheet1!$G$2:$G$333=$E41)+(Sheet1!$G$2:$G$333=$E42)+(Sheet1!$G$2:$G$333=$E43),""),"-","POST"),_xlfn._xlws.FILTER(Sheet1!$A$2:$A$333,(Sheet1!$G$2:$G$333=$E41)+(Sheet1!$G$2:$G$333=$E42)+(Sheet1!$G$2:$G$333=$E43),"UNFILLED"))} -> VANNIER, RYAN | H41: {=IF(RIGHT(_xlfn._xlws.FILTER(Sheet1!$I$2:$I$333,(Sheet1!$I$2:$I$333=$E41)+(Sheet1!$I$2:$I$333=$E42)+(Sheet1!$I$2:$I$333=$E43),""),4)="POST",CONCATENATE(_xlfn._xlws.FILTER(Sheet1!$A$2:$A$333,(Sheet1!$I$2:$I$333=$E41)+(Sheet1!$I$2:$I$333=$E42)+(Sheet1!$I$2:$I$333=$E43),""),"-","POST"),_xlfn._xlws.FILTER(Sheet1!$A$2:$A$333,(Sheet1!$I$2:$I$333=$E41)+(Sheet1!$I$2:$I$333=$E42)+(Sheet1!$I$2:$I$333=$E43),"UNFILLED"))} -> TURNER, CHERTARVEYA | I41: {=IF(RIGHT(_xlfn._xlws.FILTER(Sheet1!$K$2:$K$333,(Sheet1!$K$2:$K$333=$E41)+(Sheet1!$K$2:$K$333=$E42)+(Sheet1!$K$2:$K$333=$E43),""),4)="POST",CONCATENATE(_xlfn._xlws.FILTER(Sheet1!$A$2:$A$333,(Sheet1!$K$2:$K$333=$E41)+(Sheet1!$K$2:$K$333=$E42)+(Sheet1!$K$2:$K$333=$E43),""),"-","POST"),_xlfn._xlws.FILTER(Sheet1!$A$2:$A$333,(Sheet1!$K$2:$K$333=$E41)+(Sheet1!$K$2:$K$333=$E42)+(Sheet1!$K$2:$K$333=$E43),"UNFILLED"))} -> TURNER, CHERTARVEYA | J41: {=IF(RIGHT(_xlfn._xlws.FILTER(Sheet1!M$2:M$333,(Sheet1!M$2:M$333=$E41)+(Sheet1!M$2:M$333=$E42)+(Sheet1!M$2:M$333=$E43),""),4)="POST",CONCATENATE(_xlfn._xlws.FILTER(Sheet1!$A$2:$A$333,(Sheet1!M$2:M$333=$E41)+(Sheet1!M$2:M$333=$E42)+(Sheet1!M$2:M$333=$E43),""),"-","POST"),_xlfn._xlws.FILTER(Sheet1!$A$2:$A$333,(Sheet1!M$2:M$333=$E41)+(Sheet1!M$2:M$333=$E42)+(Sheet1!M$2:M$333=$E43),"UNFILLED"))} -> VANNIER, RYAN | K41: {=IF(RIGHT(_xlfn._xlws.FILTER(Sheet1!$O$2:$O$333,(Sheet1!$O$2:$O$333=$E41)+(Sheet1!$O$2:$O$333=$E42)+(Sheet1!$O$2:$O$333=$E43),""),4)="POST",CONCATENATE(_xlfn._xlws.FILTER(Sheet1!$A$2:$A$333,(Sheet1!$O$2:$O$333=$E41)+(Sheet1!$O$2:$O$333=$E42)+(Sheet1!$O$2:$O$333=$E43),""),"-","POST"),_xlfn._xlws.FILTER(Sheet1!$A$2:$A$333,(Sheet1!$O$2:$O$333=$E41)+(Sheet1!$O$2:$O$333=$E42)+(Sheet1!$O$2:$O$333=$E43),"UNFILLED"))} -> VANNIER, RYAN | L41: {=IF(RIGHT(_xlfn._xlws.FILTER(Sheet1!$Q$2:$Q$333,(Sheet1!$Q$2:$Q$333=$E41)+(Sheet1!$Q$2:$Q$333=$E42)+(Sheet1!$Q$2:$Q$333=$E43),""),4)="POST",CONCATENATE(_xlfn._xlws.FILTER(Sheet1!$A$2:$A$333,(Sheet1!$Q$2:$Q$333=$E41)+(Sheet1!$Q$2:$Q$333=$E42)+(Sheet1!$Q$2:$Q$333=$E43),""),"-","POST"),_xlfn._xlws.FILTER(Sheet1!$A$2:$A$333,(Sheet1!$Q$2:$Q$333=$E41)+(Sheet1!$Q$2:$Q$333=$E42)+(Sheet1!$Q$2:$Q$333=$E43),"UNFILLED"))} -> VANNIER, RYAN | M41: {=IF(RIGHT(_xlfn._xlws.FILTER(Sheet1!$S$2:$S$333,(Sheet1!$S$2:$S$333=$E41)+(Sheet1!$S$2:$S$333=$E42)+(Sheet1!$S$2:$S$333=$E43),""),4)="POST",CONCATENATE(_xlfn._xlws.FILTER(Sheet1!$A$2:$A$333,(Sheet1!$S$2:$S$333=$E41)+(Sheet1!$S$2:$S$333=$E42)+(Sheet1!$S$2:$S$333=$E43),""),"-","POST"),_xlfn._xlws.FILTER(Sheet1!$A$2:$A$333,(Sheet1!$S$2:$S$333=$E41)+(Sheet1!$S$2:$S$333=$E42)+(Sheet1!$S$2:$S$333=$E43),"UNFILLED"))} -> VANNIER, RYAN
E42: =_xlfn.CONCAT(E41,"-","POST") -> TT-1-POST
...

Sheet NORTHERN REGION ROSTER
D1: DISPATCHER NAME | F1: DIVISON | G1: OWNED ASSIGNMENT | H1: TEMP ASSIGNMENT | I1: =Sheet1!F1 -> 45969 | K1: =+I1+1 -> 45970 | M1: =+K1+1 -> 45971 | O1: =+M1+1 -> 45972 | Q1: =+O1+1 -> 45973 | S1: =+Q1+1 -> 45974 | U1: =+S1+1 -> 45975 | AC1: northern | AD1: NORTHERN ACD
I2: =TEXT(I1,"dddd") -> Saturday | K2: =TEXT(K1,"dddd") -> Sunday | M2: =TEXT(M1,"dddd") -> Monday | O2: =TEXT(O1,"dddd") -> Tuesday | Q2: =TEXT(Q1,"dddd") -> Wednesday | S2: =TEXT(S1,"dddd") -> Thursday | U2: =TEXT(U1,"dddd") -> Friday | AC2: RELIEF ACD | AD2: NORTHERN GAD
